mauriciodioli@gmail.com
Nuevo access_token generado para: mauriciodioli@gmail.com
____INTENTO ENTRAR____
127.0.0.1
mauriciodioli@gmail.com
demo@gmail.com
Debugging message: Configuración de logger completada.
Este es un mensaje de info.
Este es un mensaje de advertencia.
Este es un mensaje de error.
Este es un mensaje crítico.
Debugging message: Configuración de logger completada.
Este es un mensaje de info.
Este es un mensaje de advertencia.
Este es un mensaje de error.
Este es un mensaje crítico.
Debugging message: Configuración de logger completada.
Este es un mensaje de info.
Este es un mensaje de advertencia.
Este es un mensaje de error.
Este es un mensaje crítico.
Debugging message: Configuración de logger completada.
Este es un mensaje de info.
Este es un mensaje de advertencia.
Este es un mensaje de error.
Este es un mensaje crítico.
Debugging message: Configuración de logger completada.
Este es un mensaje de info.
Este es un mensaje de advertencia.
Este es un mensaje de error.
Este es un mensaje crítico.
Debugging message: Configuración de logger completada.
Este es un mensaje de info.
Este es un mensaje de advertencia.
Este es un mensaje de error.
Este es un mensaje crítico.
Debugging message: Configuración de logger completada.
Este es un mensaje de info.
Este es un mensaje de advertencia.
Este es un mensaje de error.
Este es un mensaje crítico.
demo@gmail.com
Debugging message: Configuración de logger completada.
Este es un mensaje de info.
Este es un mensaje de advertencia.
Este es un mensaje de error.
Este es un mensaje crítico.
Debugging message: Configuración de logger completada.
Este es un mensaje de info.
Este es un mensaje de advertencia.
Este es un mensaje de error.
Este es un mensaje crítico.
Debugging message: Configuración de logger completada.
Este es un mensaje de info.
Este es un mensaje de advertencia.
Este es un mensaje de error.
Este es un mensaje crítico.
demo@gmail.com
demo@gmail.com
Debugging message: Configuración de logger completada.
Este es un mensaje de info.
Este es un mensaje de advertencia.
Este es un mensaje de error.
Este es un mensaje crítico.
demo@gmail.com
Debugging message: Configuración de logger completada.
Este es un mensaje de info.
Este es un mensaje de advertencia.
Este es un mensaje de error.
Este es un mensaje crítico.
Debugging message: Configuración de logger completada.
Este es un mensaje de info.
Este es un mensaje de advertencia.
Este es un mensaje de error.
Este es un mensaje crítico.
Debugging message: Configuración de logger completada.
Este es un mensaje de info.
Este es un mensaje de advertencia.
Este es un mensaje de error.
Este es un mensaje crítico.
Debugging message: Configuración de logger completada.
Este es un mensaje de info.
Este es un mensaje de advertencia.
Este es un mensaje de error.
Este es un mensaje crítico.
Debugging message: Configuración de logger completada.
Este es un mensaje de info.
Este es un mensaje de advertencia.
Este es un mensaje de error.
Este es un mensaje crítico.
demo@gmail.com
mauriciodioli@gmail.com
mauriciodioli@gmail.com
mauriciodioli@gmail.com
Debugging message: Configuración de logger completada.
Este es un mensaje de info.
Este es un mensaje de advertencia.
Este es un mensaje de error.
Este es un mensaje crítico.
Debugging message: Configuración de logger completada.
Este es un mensaje de info.
Este es un mensaje de advertencia.
Este es un mensaje de error.
Este es un mensaje crítico.
mauriciodioli@gmail.com
demo@gmail.com
Debugging message: Configuración de logger completada.
Este es un mensaje de info.
Este es un mensaje de advertencia.
Este es un mensaje de error.
Este es un mensaje crítico.
demo@gmail.com
demo@gmail.com
Debugging message: Configuración de logger completada.
Este es un mensaje de info.
Este es un mensaje de advertencia.
Este es un mensaje de error.
Este es un mensaje crítico.
Debugging message: Configuración de logger completada.
Este es un mensaje de info.
Este es un mensaje de advertencia.
Este es un mensaje de error.
Este es un mensaje crítico.
Debugging message: Configuración de logger completada.
Este es un mensaje de info.
Este es un mensaje de advertencia.
Este es un mensaje de error.
Este es un mensaje crítico.
Debugging message: Configuración de logger completada.
Este es un mensaje de info.
Este es un mensaje de advertencia.
Este es un mensaje de error.
Este es un mensaje crítico.
Debugging message: Configuración de logger completada.
Este es un mensaje de info.
Este es un mensaje de advertencia.
Este es un mensaje de error.
Este es un mensaje crítico.
Debugging message: Configuración de logger completada.
Este es un mensaje de info.
Este es un mensaje de advertencia.
Este es un mensaje de error.
Este es un mensaje crítico.
Debugging message: Configuración de logger completada.
Este es un mensaje de info.
Este es un mensaje de advertencia.
Este es un mensaje de error.
Este es un mensaje crítico.
Debugging message: Configuración de logger completada.
Este es un mensaje de info.
Este es un mensaje de advertencia.
Este es un mensaje de error.
Este es un mensaje crítico.
Debugging message: Configuración de logger completada.
Este es un mensaje de info.
Este es un mensaje de advertencia.
Este es un mensaje de error.
Este es un mensaje crítico.
demo@gmail.com
Debugging message: Configuración de logger completada.
Este es un mensaje de info.
Este es un mensaje de advertencia.
Este es un mensaje de error.
Este es un mensaje crítico.
Debugging message: Configuración de logger completada.
Este es un mensaje de info.
Este es un mensaje de advertencia.
Este es un mensaje de error.
Este es un mensaje crítico.
Debugging message: Configuración de logger completada.
Este es un mensaje de info.
Este es un mensaje de advertencia.
Este es un mensaje de error.
Este es un mensaje crítico.
Debugging message: Configuración de logger completada.
Este es un mensaje de info.
Este es un mensaje de advertencia.
Este es un mensaje de error.
Este es un mensaje crítico.
Debugging message: Configuración de logger completada.
Este es un mensaje de info.
Este es un mensaje de advertencia.
Este es un mensaje de error.
Este es un mensaje crítico.
Debugging message: Configuración de logger completada.
Este es un mensaje de info.
Este es un mensaje de advertencia.
Este es un mensaje de error.
Este es un mensaje crítico.
Debugging message: Configuración de logger completada.
Este es un mensaje de info.
Este es un mensaje de advertencia.
Este es un mensaje de error.
Este es un mensaje crítico.
demo@gmail.com
demo@gmail.com
Debugging message: Configuración de logger completada.
Este es un mensaje de info.
Este es un mensaje de advertencia.
Este es un mensaje de error.
Este es un mensaje crítico.
Debugging message: Configuración de logger completada.
Este es un mensaje de info.
Este es un mensaje de advertencia.
Este es un mensaje de error.
Este es un mensaje crítico.
demo@gmail.com
Debugging message: Configuración de logger completada.
Este es un mensaje de info.
Este es un mensaje de advertencia.
Este es un mensaje de error.
Este es un mensaje crítico.
demo@gmail.com
Debugging message: Configuración de logger completada.
Este es un mensaje de info.
Este es un mensaje de advertencia.
Este es un mensaje de error.
Este es un mensaje crítico.
Debugging message: Configuración de logger completada.
Este es un mensaje de info.
Este es un mensaje de advertencia.
Este es un mensaje de error.
Este es un mensaje crítico.
Debugging message: Configuración de logger completada.
Este es un mensaje de info.
Este es un mensaje de advertencia.
Este es un mensaje de error.
Este es un mensaje crítico.
Debugging message: Configuración de logger completada.
Este es un mensaje de info.
Este es un mensaje de advertencia.
Este es un mensaje de error.
Este es un mensaje crítico.
demo@gmail.com
demo@gmail.com
Debugging message: Configuración de logger completada.
Este es un mensaje de info.
Este es un mensaje de advertencia.
Este es un mensaje de error.
Este es un mensaje crítico.
Debugging message: Configuración de logger completada.
Este es un mensaje de info.
Este es un mensaje de advertencia.
Este es un mensaje de error.
Este es un mensaje crítico.
Debugging message: Configuración de logger completada.
Este es un mensaje de info.
Este es un mensaje de advertencia.
Este es un mensaje de error.
Este es un mensaje crítico.
demo@gmail.com
LEE EL SHEET POR LLAMADA DE FUNCION
demo@gmail.com
LEE EL SHEET POR LLAMADA DE FUNCION
Debugging message: Configuración de logger completada.
Este es un mensaje de info.
Este es un mensaje de advertencia.
Este es un mensaje de error.
Este es un mensaje crítico.
Debugging message: Configuración de logger completada.
Este es un mensaje de info.
Este es un mensaje de advertencia.
Este es un mensaje de error.
Este es un mensaje crítico.
LEE EL SHEET POR LLAMADA DE FUNCION
demo@gmail.com
LEE EL SHEET POR LLAMADA DE FUNCION
Debugging message: Configuración de logger completada.
Este es un mensaje de info.
Este es un mensaje de advertencia.
Este es un mensaje de error.
Este es un mensaje crítico.
Debugging message: Configuración de logger completada.
Este es un mensaje de info.
Este es un mensaje de advertencia.
Este es un mensaje de error.
Este es un mensaje crítico.
____INTENTO ENTRAR____
127.0.0.1
None
Error registrando acceso: (pymysql.err.OperationalError) (1054, "Unknown column 'codigoPostal' in 'field list'")
[SQL: INSERT INTO logs (user_id, `userCuenta`, `accountCuenta`, fecha_log, ip, funcion, archivo, linea, error, `codigoPostal`, latitude, longitude, language) VALUES (%(user_id)s, %(userCuenta)s, %(accountCuenta)s, %(fecha_log)s, %(ip)s, %(funcion)s, %(archivo)s, %(linea)s, %(error)s, %(codigoPostal)s, %(latitude)s, %(longitude)s, %(language)s)]
[parameters: {'user_id': 28, 'userCuenta': 'usuario@example.com', 'accountCuenta': 'usuario@example.com', 'fecha_log': datetime.datetime(2025, 6, 22, 19, 44, 6, 899626), 'ip': '5.90.224.61', 'funcion': 'log_acceso', 'archivo': 'logRegister.py', 'linea': 608, 'error': 'No hubo error', 'codigoPostal': '12345', 'latitude': '40.8522', 'longitude': '14.2681', 'language': 'in'}]
(Background on this error at: https://sqlalche.me/e/14/e3q8)
Error registrando acceso: (pymysql.err.OperationalError) (1054, "Unknown column 'codigoPostal' in 'field list'")
[SQL: INSERT INTO logs (user_id, `userCuenta`, `accountCuenta`, fecha_log, ip, funcion, archivo, linea, error, `codigoPostal`, latitude, longitude, language) VALUES (%(user_id)s, %(userCuenta)s, %(accountCuenta)s, %(fecha_log)s, %(ip)s, %(funcion)s, %(archivo)s, %(linea)s, %(error)s, %(codigoPostal)s, %(latitude)s, %(longitude)s, %(language)s)]
[parameters: {'user_id': 28, 'userCuenta': 'usuario@example.com', 'accountCuenta': 'usuario@example.com', 'fecha_log': datetime.datetime(2025, 6, 22, 19, 53, 38, 95789), 'ip': '5.90.224.61', 'funcion': 'log_acceso', 'archivo': 'logRegister.py', 'linea': 608, 'error': 'No hubo error', 'codigoPostal': '12345', 'latitude': '40.8522', 'longitude': '14.2681', 'language': 'es'}]
(Background on this error at: https://sqlalche.me/e/14/e3q8)
LEE EL SHEET POR LLAMADA DE FUNCION
Exception on /panel_control_sin_cuenta/ [GET]
Traceback (most recent call last):
  File "/usr/local/lib/python3.9/site-packages/flask/app.py", line 2528, in wsgi_app
    response = self.full_dispatch_request()
  File "/usr/local/lib/python3.9/site-packages/flask/app.py", line 1825, in full_dispatch_request
    rv = self.handle_user_exception(e)
  File "/usr/local/lib/python3.9/site-packages/flask_cors/extension.py", line 165, in wrapped_function
    return cors_after_request(app.make_response(f(*args, **kwargs)))
  File "/usr/local/lib/python3.9/site-packages/flask/app.py", line 1823, in full_dispatch_request
    rv = self.dispatch_request()
  File "/usr/local/lib/python3.9/site-packages/flask/app.py", line 1799, in dispatch_request
    return self.ensure_sync(self.view_functions[rule.endpoint])(**view_args)
  File "/workspaces/bot421/src/panelControlBroker/panelControl.py", line 58, in panel_control_sin_cuenta
    datos_desempaquetados = procesar_datos(app,pais, account,usuario_id,selector)
  File "/workspaces/bot421/src/panelControlBroker/panelControl.py", line 342, in procesar_datos
    enviar_leer_sheet(app,pais,user_id,accountCuenta,None,selector)
  File "/workspaces/bot421/src/panelControlBroker/panelControl.py", line 301, in enviar_leer_sheet
    ContenidoSheetList = list(ContenidoSheet)
TypeError: 'NoneType' object is not iterable
Error registrando acceso: (pymysql.err.OperationalError) (1054, "Unknown column 'codigoPostal' in 'field list'")
[SQL: INSERT INTO logs (user_id, `userCuenta`, `accountCuenta`, fecha_log, ip, funcion, archivo, linea, error, `codigoPostal`, latitude, longitude, language) VALUES (%(user_id)s, %(userCuenta)s, %(accountCuenta)s, %(fecha_log)s, %(ip)s, %(funcion)s, %(archivo)s, %(linea)s, %(error)s, %(codigoPostal)s, %(latitude)s, %(longitude)s, %(language)s)]
[parameters: {'user_id': 28, 'userCuenta': 'usuario@example.com', 'accountCuenta': 'usuario@example.com', 'fecha_log': datetime.datetime(2025, 6, 22, 19, 58, 9, 300350), 'ip': '5.90.224.61', 'funcion': 'log_acceso', 'archivo': 'logRegister.py', 'linea': 608, 'error': 'No hubo error', 'codigoPostal': '4139', 'latitude': '40.8522', 'longitude': '14.2681', 'language': 'es'}]
(Background on this error at: https://sqlalche.me/e/14/e3q8)
____INTENTO ENTRAR____
127.0.0.1
None
Error registrando acceso: (pymysql.err.OperationalError) (1054, "Unknown column 'codigoPostal' in 'field list'")
[SQL: INSERT INTO logs (user_id, `userCuenta`, `accountCuenta`, fecha_log, ip, funcion, archivo, linea, error, `codigoPostal`, latitude, longitude, language) VALUES (%(user_id)s, %(userCuenta)s, %(accountCuenta)s, %(fecha_log)s, %(ip)s, %(funcion)s, %(archivo)s, %(linea)s, %(error)s, %(codigoPostal)s, %(latitude)s, %(longitude)s, %(language)s)]
[parameters: {'user_id': 28, 'userCuenta': 'usuario@example.com', 'accountCuenta': 'usuario@example.com', 'fecha_log': datetime.datetime(2025, 6, 22, 20, 12, 3, 531646), 'ip': '5.90.224.61', 'funcion': 'log_acceso', 'archivo': 'logRegister.py', 'linea': 608, 'error': 'No hubo error', 'codigoPostal': '12345', 'latitude': '40.8522', 'longitude': '14.2681', 'language': 'es'}]
(Background on this error at: https://sqlalche.me/e/14/e3q8)
Error registrando acceso: (pymysql.err.OperationalError) (1054, "Unknown column 'codigoPostal' in 'field list'")
[SQL: INSERT INTO logs (user_id, `userCuenta`, `accountCuenta`, fecha_log, ip, funcion, archivo, linea, error, `codigoPostal`, latitude, longitude, language) VALUES (%(user_id)s, %(userCuenta)s, %(accountCuenta)s, %(fecha_log)s, %(ip)s, %(funcion)s, %(archivo)s, %(linea)s, %(error)s, %(codigoPostal)s, %(latitude)s, %(longitude)s, %(language)s)]
[parameters: {'user_id': 28, 'userCuenta': 'usuario@example.com', 'accountCuenta': 'usuario@example.com', 'fecha_log': datetime.datetime(2025, 6, 22, 20, 41, 3, 784345), 'ip': '5.90.224.61', 'funcion': 'log_acceso', 'archivo': 'logRegister.py', 'linea': 608, 'error': 'No hubo error', 'codigoPostal': '12345', 'latitude': '40.8522', 'longitude': '14.2681', 'language': 'es'}]
(Background on this error at: https://sqlalche.me/e/14/e3q8)
Error registrando acceso: (pymysql.err.OperationalError) (1054, "Unknown column 'codigoPostal' in 'field list'")
[SQL: INSERT INTO logs (user_id, `userCuenta`, `accountCuenta`, fecha_log, ip, funcion, archivo, linea, error, `codigoPostal`, latitude, longitude, language) VALUES (%(user_id)s, %(userCuenta)s, %(accountCuenta)s, %(fecha_log)s, %(ip)s, %(funcion)s, %(archivo)s, %(linea)s, %(error)s, %(codigoPostal)s, %(latitude)s, %(longitude)s, %(language)s)]
[parameters: {'user_id': 28, 'userCuenta': 'usuario@example.com', 'accountCuenta': 'usuario@example.com', 'fecha_log': datetime.datetime(2025, 6, 22, 20, 46, 52, 934472), 'ip': '5.90.224.61', 'funcion': 'log_acceso', 'archivo': 'logRegister.py', 'linea': 608, 'error': 'No hubo error', 'codigoPostal': '12345', 'latitude': '40.8522', 'longitude': '14.2681', 'language': 'es'}]
(Background on this error at: https://sqlalche.me/e/14/e3q8)
Error registrando acceso: (pymysql.err.OperationalError) (1054, "Unknown column 'codigoPostal' in 'field list'")
[SQL: INSERT INTO logs (user_id, `userCuenta`, `accountCuenta`, fecha_log, ip, funcion, archivo, linea, error, `codigoPostal`, latitude, longitude, language) VALUES (%(user_id)s, %(userCuenta)s, %(accountCuenta)s, %(fecha_log)s, %(ip)s, %(funcion)s, %(archivo)s, %(linea)s, %(error)s, %(codigoPostal)s, %(latitude)s, %(longitude)s, %(language)s)]
[parameters: {'user_id': 28, 'userCuenta': 'usuario@example.com', 'accountCuenta': 'usuario@example.com', 'fecha_log': datetime.datetime(2025, 6, 22, 20, 48, 19, 73678), 'ip': '5.90.224.61', 'funcion': 'log_acceso', 'archivo': 'logRegister.py', 'linea': 608, 'error': 'No hubo error', 'codigoPostal': '12345', 'latitude': '40.8522', 'longitude': '14.2681', 'language': 'es'}]
(Background on this error at: https://sqlalche.me/e/14/e3q8)
Error registrando acceso: (pymysql.err.OperationalError) (1054, "Unknown column 'codigoPostal' in 'field list'")
[SQL: INSERT INTO logs (user_id, `userCuenta`, `accountCuenta`, fecha_log, ip, funcion, archivo, linea, error, `codigoPostal`, latitude, longitude, language) VALUES (%(user_id)s, %(userCuenta)s, %(accountCuenta)s, %(fecha_log)s, %(ip)s, %(funcion)s, %(archivo)s, %(linea)s, %(error)s, %(codigoPostal)s, %(latitude)s, %(longitude)s, %(language)s)]
[parameters: {'user_id': 28, 'userCuenta': 'usuario@example.com', 'accountCuenta': 'usuario@example.com', 'fecha_log': datetime.datetime(2025, 6, 22, 20, 50, 26, 375863), 'ip': '5.90.224.61', 'funcion': 'log_acceso', 'archivo': 'logRegister.py', 'linea': 608, 'error': 'No hubo error', 'codigoPostal': '12345', 'latitude': '40.8522', 'longitude': '14.2681', 'language': 'es'}]
(Background on this error at: https://sqlalche.me/e/14/e3q8)
Error registrando acceso: (pymysql.err.OperationalError) (1054, "Unknown column 'codigoPostal' in 'field list'")
[SQL: INSERT INTO logs (user_id, `userCuenta`, `accountCuenta`, fecha_log, ip, funcion, archivo, linea, error, `codigoPostal`, latitude, longitude, language) VALUES (%(user_id)s, %(userCuenta)s, %(accountCuenta)s, %(fecha_log)s, %(ip)s, %(funcion)s, %(archivo)s, %(linea)s, %(error)s, %(codigoPostal)s, %(latitude)s, %(longitude)s, %(language)s)]
[parameters: {'user_id': 28, 'userCuenta': 'usuario@example.com', 'accountCuenta': 'usuario@example.com', 'fecha_log': datetime.datetime(2025, 6, 22, 20, 50, 52, 477714), 'ip': '5.90.224.61', 'funcion': 'log_acceso', 'archivo': 'logRegister.py', 'linea': 608, 'error': 'No hubo error', 'codigoPostal': '12345', 'latitude': '40.8522', 'longitude': '14.2681', 'language': 'es'}]
(Background on this error at: https://sqlalche.me/e/14/e3q8)
____INTENTO ENTRAR____
127.0.0.1
None
Error registrando acceso: (pymysql.err.OperationalError) (1054, "Unknown column 'codigoPostal' in 'field list'")
[SQL: INSERT INTO logs (user_id, `userCuenta`, `accountCuenta`, fecha_log, ip, funcion, archivo, linea, error, `codigoPostal`, latitude, longitude, language) VALUES (%(user_id)s, %(userCuenta)s, %(accountCuenta)s, %(fecha_log)s, %(ip)s, %(funcion)s, %(archivo)s, %(linea)s, %(error)s, %(codigoPostal)s, %(latitude)s, %(longitude)s, %(language)s)]
[parameters: {'user_id': 28, 'userCuenta': 'usuario@example.com', 'accountCuenta': 'usuario@example.com', 'fecha_log': datetime.datetime(2025, 6, 22, 20, 51, 10, 535047), 'ip': '5.90.224.61', 'funcion': 'log_acceso', 'archivo': 'logRegister.py', 'linea': 608, 'error': 'No hubo error', 'codigoPostal': '12345', 'latitude': '40.8522', 'longitude': '14.2681', 'language': 'es'}]
(Background on this error at: https://sqlalche.me/e/14/e3q8)
Error registrando acceso: (pymysql.err.OperationalError) (1054, "Unknown column 'codigoPostal' in 'field list'")
[SQL: INSERT INTO logs (user_id, `userCuenta`, `accountCuenta`, fecha_log, ip, funcion, archivo, linea, error, `codigoPostal`, latitude, longitude, language) VALUES (%(user_id)s, %(userCuenta)s, %(accountCuenta)s, %(fecha_log)s, %(ip)s, %(funcion)s, %(archivo)s, %(linea)s, %(error)s, %(codigoPostal)s, %(latitude)s, %(longitude)s, %(language)s)]
[parameters: {'user_id': 28, 'userCuenta': 'usuario@example.com', 'accountCuenta': 'usuario@example.com', 'fecha_log': datetime.datetime(2025, 6, 22, 20, 51, 52, 275778), 'ip': '5.90.224.61', 'funcion': 'log_acceso', 'archivo': 'logRegister.py', 'linea': 608, 'error': 'No hubo error', 'codigoPostal': '12345', 'latitude': '40.8522', 'longitude': '14.2681', 'language': 'es'}]
(Background on this error at: https://sqlalche.me/e/14/e3q8)
Error registrando acceso: (pymysql.err.OperationalError) (1054, "Unknown column 'codigoPostal' in 'field list'")
[SQL: INSERT INTO logs (user_id, `userCuenta`, `accountCuenta`, fecha_log, ip, funcion, archivo, linea, error, `codigoPostal`, latitude, longitude, language) VALUES (%(user_id)s, %(userCuenta)s, %(accountCuenta)s, %(fecha_log)s, %(ip)s, %(funcion)s, %(archivo)s, %(linea)s, %(error)s, %(codigoPostal)s, %(latitude)s, %(longitude)s, %(language)s)]
[parameters: {'user_id': 28, 'userCuenta': 'usuario@example.com', 'accountCuenta': 'usuario@example.com', 'fecha_log': datetime.datetime(2025, 6, 22, 20, 52, 46, 31798), 'ip': '5.90.224.61', 'funcion': 'log_acceso', 'archivo': 'logRegister.py', 'linea': 608, 'error': 'No hubo error', 'codigoPostal': '12345', 'latitude': '40.8522', 'longitude': '14.2681', 'language': 'es'}]
(Background on this error at: https://sqlalche.me/e/14/e3q8)
Debugging message: Configuración de logger completada.
Este es un mensaje de info.
Este es un mensaje de advertencia.
Este es un mensaje de error.
Este es un mensaje crítico.
Debugging message: Configuración de logger completada.
Este es un mensaje de info.
Este es un mensaje de advertencia.
Este es un mensaje de error.
Este es un mensaje crítico.
____INTENTO ENTRAR____
127.0.0.1
None
Error registrando acceso: (pymysql.err.OperationalError) (1054, "Unknown column 'codigoPostal' in 'field list'")
[SQL: INSERT INTO logs (user_id, `userCuenta`, `accountCuenta`, fecha_log, ip, funcion, archivo, linea, error, `codigoPostal`, latitude, longitude, language) VALUES (%(user_id)s, %(userCuenta)s, %(accountCuenta)s, %(fecha_log)s, %(ip)s, %(funcion)s, %(archivo)s, %(linea)s, %(error)s, %(codigoPostal)s, %(latitude)s, %(longitude)s, %(language)s)]
[parameters: {'user_id': 28, 'userCuenta': 'usuario@example.com', 'accountCuenta': 'usuario@example.com', 'fecha_log': datetime.datetime(2025, 6, 22, 20, 54, 30, 341681), 'ip': '5.90.224.61', 'funcion': 'log_acceso', 'archivo': 'logRegister.py', 'linea': 608, 'error': 'No hubo error', 'codigoPostal': '12345', 'latitude': '40.8522', 'longitude': '14.2681', 'language': 'es'}]
(Background on this error at: https://sqlalche.me/e/14/e3q8)
Error registrando acceso: (pymysql.err.OperationalError) (1054, "Unknown column 'codigoPostal' in 'field list'")
[SQL: INSERT INTO logs (user_id, `userCuenta`, `accountCuenta`, fecha_log, ip, funcion, archivo, linea, error, `codigoPostal`, latitude, longitude, language) VALUES (%(user_id)s, %(userCuenta)s, %(accountCuenta)s, %(fecha_log)s, %(ip)s, %(funcion)s, %(archivo)s, %(linea)s, %(error)s, %(codigoPostal)s, %(latitude)s, %(longitude)s, %(language)s)]
[parameters: {'user_id': 28, 'userCuenta': 'usuario@example.com', 'accountCuenta': 'usuario@example.com', 'fecha_log': datetime.datetime(2025, 6, 22, 20, 54, 47, 545629), 'ip': '5.90.224.61', 'funcion': 'log_acceso', 'archivo': 'logRegister.py', 'linea': 608, 'error': 'No hubo error', 'codigoPostal': '12345', 'latitude': '40.8522', 'longitude': '14.2681', 'language': 'es'}]
(Background on this error at: https://sqlalche.me/e/14/e3q8)
Error registrando acceso: (pymysql.err.OperationalError) (1054, "Unknown column 'codigoPostal' in 'field list'")
[SQL: INSERT INTO logs (user_id, `userCuenta`, `accountCuenta`, fecha_log, ip, funcion, archivo, linea, error, `codigoPostal`, latitude, longitude, language) VALUES (%(user_id)s, %(userCuenta)s, %(accountCuenta)s, %(fecha_log)s, %(ip)s, %(funcion)s, %(archivo)s, %(linea)s, %(error)s, %(codigoPostal)s, %(latitude)s, %(longitude)s, %(language)s)]
[parameters: {'user_id': 28, 'userCuenta': 'usuario@example.com', 'accountCuenta': 'usuario@example.com', 'fecha_log': datetime.datetime(2025, 6, 22, 21, 16, 50, 212105), 'ip': '5.90.224.61', 'funcion': 'log_acceso', 'archivo': 'logRegister.py', 'linea': 608, 'error': 'No hubo error', 'codigoPostal': '12345', 'latitude': '40.8522', 'longitude': '14.2681', 'language': 'es'}]
(Background on this error at: https://sqlalche.me/e/14/e3q8)
Error registrando acceso: (pymysql.err.OperationalError) (1054, "Unknown column 'codigoPostal' in 'field list'")
[SQL: INSERT INTO logs (user_id, `userCuenta`, `accountCuenta`, fecha_log, ip, funcion, archivo, linea, error, `codigoPostal`, latitude, longitude, language) VALUES (%(user_id)s, %(userCuenta)s, %(accountCuenta)s, %(fecha_log)s, %(ip)s, %(funcion)s, %(archivo)s, %(linea)s, %(error)s, %(codigoPostal)s, %(latitude)s, %(longitude)s, %(language)s)]
[parameters: {'user_id': 28, 'userCuenta': 'usuario@example.com', 'accountCuenta': 'usuario@example.com', 'fecha_log': datetime.datetime(2025, 6, 22, 21, 35, 22, 230351), 'ip': '5.90.224.61', 'funcion': 'log_acceso', 'archivo': 'logRegister.py', 'linea': 608, 'error': 'No hubo error', 'codigoPostal': '12345', 'latitude': '40.8522', 'longitude': '14.2681', 'language': 'es'}]
(Background on this error at: https://sqlalche.me/e/14/e3q8)
Error registrando acceso: (pymysql.err.OperationalError) (1054, "Unknown column 'codigoPostal' in 'field list'")
[SQL: INSERT INTO logs (user_id, `userCuenta`, `accountCuenta`, fecha_log, ip, funcion, archivo, linea, error, `codigoPostal`, latitude, longitude, language) VALUES (%(user_id)s, %(userCuenta)s, %(accountCuenta)s, %(fecha_log)s, %(ip)s, %(funcion)s, %(archivo)s, %(linea)s, %(error)s, %(codigoPostal)s, %(latitude)s, %(longitude)s, %(language)s)]
[parameters: {'user_id': 28, 'userCuenta': 'usuario@example.com', 'accountCuenta': 'usuario@example.com', 'fecha_log': datetime.datetime(2025, 6, 22, 21, 36, 24, 34967), 'ip': '5.90.224.61', 'funcion': 'log_acceso', 'archivo': 'logRegister.py', 'linea': 608, 'error': 'No hubo error', 'codigoPostal': '12345', 'latitude': '40.8522', 'longitude': '14.2681', 'language': 'es'}]
(Background on this error at: https://sqlalche.me/e/14/e3q8)
Error registrando acceso: (pymysql.err.OperationalError) (1054, "Unknown column 'codigoPostal' in 'field list'")
[SQL: INSERT INTO logs (user_id, `userCuenta`, `accountCuenta`, fecha_log, ip, funcion, archivo, linea, error, `codigoPostal`, latitude, longitude, language) VALUES (%(user_id)s, %(userCuenta)s, %(accountCuenta)s, %(fecha_log)s, %(ip)s, %(funcion)s, %(archivo)s, %(linea)s, %(error)s, %(codigoPostal)s, %(latitude)s, %(longitude)s, %(language)s)]
[parameters: {'user_id': 28, 'userCuenta': 'usuario@example.com', 'accountCuenta': 'usuario@example.com', 'fecha_log': datetime.datetime(2025, 6, 22, 21, 36, 44, 560416), 'ip': '5.90.224.61', 'funcion': 'log_acceso', 'archivo': 'logRegister.py', 'linea': 608, 'error': 'No hubo error', 'codigoPostal': '12345', 'latitude': '40.8522', 'longitude': '14.2681', 'language': 'es'}]
(Background on this error at: https://sqlalche.me/e/14/e3q8)
Error registrando acceso: (pymysql.err.OperationalError) (1054, "Unknown column 'codigoPostal' in 'field list'")
[SQL: INSERT INTO logs (user_id, `userCuenta`, `accountCuenta`, fecha_log, ip, funcion, archivo, linea, error, `codigoPostal`, latitude, longitude, language) VALUES (%(user_id)s, %(userCuenta)s, %(accountCuenta)s, %(fecha_log)s, %(ip)s, %(funcion)s, %(archivo)s, %(linea)s, %(error)s, %(codigoPostal)s, %(latitude)s, %(longitude)s, %(language)s)]
[parameters: {'user_id': 28, 'userCuenta': 'usuario@example.com', 'accountCuenta': 'usuario@example.com', 'fecha_log': datetime.datetime(2025, 6, 22, 21, 37, 0, 757225), 'ip': '5.90.224.61', 'funcion': 'log_acceso', 'archivo': 'logRegister.py', 'linea': 608, 'error': 'No hubo error', 'codigoPostal': '12345', 'latitude': '40.8522', 'longitude': '14.2681', 'language': 'es'}]
(Background on this error at: https://sqlalche.me/e/14/e3q8)
Error registrando acceso: (pymysql.err.OperationalError) (1054, "Unknown column 'codigoPostal' in 'field list'")
[SQL: INSERT INTO logs (user_id, `userCuenta`, `accountCuenta`, fecha_log, ip, funcion, archivo, linea, error, `codigoPostal`, latitude, longitude, language) VALUES (%(user_id)s, %(userCuenta)s, %(accountCuenta)s, %(fecha_log)s, %(ip)s, %(funcion)s, %(archivo)s, %(linea)s, %(error)s, %(codigoPostal)s, %(latitude)s, %(longitude)s, %(language)s)]
[parameters: {'user_id': 28, 'userCuenta': 'usuario@example.com', 'accountCuenta': 'usuario@example.com', 'fecha_log': datetime.datetime(2025, 6, 22, 21, 37, 34, 389359), 'ip': '5.90.224.61', 'funcion': 'log_acceso', 'archivo': 'logRegister.py', 'linea': 608, 'error': 'No hubo error', 'codigoPostal': '12345', 'latitude': '40.8522', 'longitude': '14.2681', 'language': 'es'}]
(Background on this error at: https://sqlalche.me/e/14/e3q8)
Error registrando acceso: (pymysql.err.OperationalError) (1054, "Unknown column 'codigoPostal' in 'field list'")
[SQL: INSERT INTO logs (user_id, `userCuenta`, `accountCuenta`, fecha_log, ip, funcion, archivo, linea, error, `codigoPostal`, latitude, longitude, language) VALUES (%(user_id)s, %(userCuenta)s, %(accountCuenta)s, %(fecha_log)s, %(ip)s, %(funcion)s, %(archivo)s, %(linea)s, %(error)s, %(codigoPostal)s, %(latitude)s, %(longitude)s, %(language)s)]
[parameters: {'user_id': 28, 'userCuenta': 'usuario@example.com', 'accountCuenta': 'usuario@example.com', 'fecha_log': datetime.datetime(2025, 6, 22, 21, 38, 22, 559284), 'ip': '5.90.224.61', 'funcion': 'log_acceso', 'archivo': 'logRegister.py', 'linea': 608, 'error': 'No hubo error', 'codigoPostal': '4139', 'latitude': '40.8522', 'longitude': '14.2681', 'language': 'es'}]
(Background on this error at: https://sqlalche.me/e/14/e3q8)
Error registrando acceso: (pymysql.err.OperationalError) (1054, "Unknown column 'codigoPostal' in 'field list'")
[SQL: INSERT INTO logs (user_id, `userCuenta`, `accountCuenta`, fecha_log, ip, funcion, archivo, linea, error, `codigoPostal`, latitude, longitude, language) VALUES (%(user_id)s, %(userCuenta)s, %(accountCuenta)s, %(fecha_log)s, %(ip)s, %(funcion)s, %(archivo)s, %(linea)s, %(error)s, %(codigoPostal)s, %(latitude)s, %(longitude)s, %(language)s)]
[parameters: {'user_id': 28, 'userCuenta': 'usuario@example.com', 'accountCuenta': 'usuario@example.com', 'fecha_log': datetime.datetime(2025, 6, 22, 21, 43, 40, 83736), 'ip': '5.90.224.61', 'funcion': 'log_acceso', 'archivo': 'logRegister.py', 'linea': 608, 'error': 'No hubo error', 'codigoPostal': '4139', 'latitude': '40.8522', 'longitude': '14.2681', 'language': 'es'}]
(Background on this error at: https://sqlalche.me/e/14/e3q8)
Error registrando acceso: (pymysql.err.OperationalError) (1054, "Unknown column 'codigoPostal' in 'field list'")
[SQL: INSERT INTO logs (user_id, `userCuenta`, `accountCuenta`, fecha_log, ip, funcion, archivo, linea, error, `codigoPostal`, latitude, longitude, language) VALUES (%(user_id)s, %(userCuenta)s, %(accountCuenta)s, %(fecha_log)s, %(ip)s, %(funcion)s, %(archivo)s, %(linea)s, %(error)s, %(codigoPostal)s, %(latitude)s, %(longitude)s, %(language)s)]
[parameters: {'user_id': 28, 'userCuenta': 'usuario@example.com', 'accountCuenta': 'usuario@example.com', 'fecha_log': datetime.datetime(2025, 6, 22, 21, 43, 57, 412723), 'ip': '5.90.224.61', 'funcion': 'log_acceso', 'archivo': 'logRegister.py', 'linea': 608, 'error': 'No hubo error', 'codigoPostal': '4139', 'latitude': '40.8522', 'longitude': '14.2681', 'language': 'es'}]
(Background on this error at: https://sqlalche.me/e/14/e3q8)
Error registrando acceso: (pymysql.err.OperationalError) (1054, "Unknown column 'codigoPostal' in 'field list'")
[SQL: INSERT INTO logs (user_id, `userCuenta`, `accountCuenta`, fecha_log, ip, funcion, archivo, linea, error, `codigoPostal`, latitude, longitude, language) VALUES (%(user_id)s, %(userCuenta)s, %(accountCuenta)s, %(fecha_log)s, %(ip)s, %(funcion)s, %(archivo)s, %(linea)s, %(error)s, %(codigoPostal)s, %(latitude)s, %(longitude)s, %(language)s)]
[parameters: {'user_id': 28, 'userCuenta': 'usuario@example.com', 'accountCuenta': 'usuario@example.com', 'fecha_log': datetime.datetime(2025, 6, 23, 1, 59, 23, 715308), 'ip': '5.91.157.10', 'funcion': 'log_acceso', 'archivo': 'logRegister.py', 'linea': 608, 'error': 'No hubo error', 'codigoPostal': '4139', 'latitude': '40.8522', 'longitude': '14.2681', 'language': 'es'}]
(Background on this error at: https://sqlalche.me/e/14/e3q8)
Error registrando acceso: (pymysql.err.OperationalError) (1054, "Unknown column 'codigoPostal' in 'field list'")
[SQL: INSERT INTO logs (user_id, `userCuenta`, `accountCuenta`, fecha_log, ip, funcion, archivo, linea, error, `codigoPostal`, latitude, longitude, language) VALUES (%(user_id)s, %(userCuenta)s, %(accountCuenta)s, %(fecha_log)s, %(ip)s, %(funcion)s, %(archivo)s, %(linea)s, %(error)s, %(codigoPostal)s, %(latitude)s, %(longitude)s, %(language)s)]
[parameters: {'user_id': 28, 'userCuenta': 'usuario@example.com', 'accountCuenta': 'usuario@example.com', 'fecha_log': datetime.datetime(2025, 6, 23, 2, 13, 35, 869679), 'ip': '5.91.157.10', 'funcion': 'log_acceso', 'archivo': 'logRegister.py', 'linea': 608, 'error': 'No hubo error', 'codigoPostal': '4139', 'latitude': '40.8522', 'longitude': '14.2681', 'language': 'es'}]
(Background on this error at: https://sqlalche.me/e/14/e3q8)
____INTENTO ENTRAR____
127.0.0.1
None
Error registrando acceso: (pymysql.err.OperationalError) (1054, "Unknown column 'codigoPostal' in 'field list'")
[SQL: INSERT INTO logs (user_id, `userCuenta`, `accountCuenta`, fecha_log, ip, funcion, archivo, linea, error, `codigoPostal`, latitude, longitude, language) VALUES (%(user_id)s, %(userCuenta)s, %(accountCuenta)s, %(fecha_log)s, %(ip)s, %(funcion)s, %(archivo)s, %(linea)s, %(error)s, %(codigoPostal)s, %(latitude)s, %(longitude)s, %(language)s)]
[parameters: {'user_id': 28, 'userCuenta': 'usuario@example.com', 'accountCuenta': 'usuario@example.com', 'fecha_log': datetime.datetime(2025, 6, 23, 2, 14, 38, 404130), 'ip': '5.91.157.10', 'funcion': 'log_acceso', 'archivo': 'logRegister.py', 'linea': 608, 'error': 'No hubo error', 'codigoPostal': '12345', 'latitude': '41.8919', 'longitude': '12.5113', 'language': 'es'}]
(Background on this error at: https://sqlalche.me/e/14/e3q8)
____INTENTO ENTRAR____
127.0.0.1
None
Error registrando acceso: (pymysql.err.OperationalError) (1054, "Unknown column 'codigoPostal' in 'field list'")
[SQL: INSERT INTO logs (user_id, `userCuenta`, `accountCuenta`, fecha_log, ip, funcion, archivo, linea, error, `codigoPostal`, latitude, longitude, language) VALUES (%(user_id)s, %(userCuenta)s, %(accountCuenta)s, %(fecha_log)s, %(ip)s, %(funcion)s, %(archivo)s, %(linea)s, %(error)s, %(codigoPostal)s, %(latitude)s, %(longitude)s, %(language)s)]
[parameters: {'user_id': 28, 'userCuenta': 'usuario@example.com', 'accountCuenta': 'usuario@example.com', 'fecha_log': datetime.datetime(2025, 6, 23, 2, 15, 27, 61625), 'ip': '5.91.157.10', 'funcion': 'log_acceso', 'archivo': 'logRegister.py', 'linea': 608, 'error': 'No hubo error', 'codigoPostal': '12345', 'latitude': '41.8919', 'longitude': '12.5113', 'language': 'es'}]
(Background on this error at: https://sqlalche.me/e/14/e3q8)
Error registrando acceso: (pymysql.err.OperationalError) (1054, "Unknown column 'codigoPostal' in 'field list'")
[SQL: INSERT INTO logs (user_id, `userCuenta`, `accountCuenta`, fecha_log, ip, funcion, archivo, linea, error, `codigoPostal`, latitude, longitude, language) VALUES (%(user_id)s, %(userCuenta)s, %(accountCuenta)s, %(fecha_log)s, %(ip)s, %(funcion)s, %(archivo)s, %(linea)s, %(error)s, %(codigoPostal)s, %(latitude)s, %(longitude)s, %(language)s)]
[parameters: {'user_id': 28, 'userCuenta': 'usuario@example.com', 'accountCuenta': 'usuario@example.com', 'fecha_log': datetime.datetime(2025, 6, 23, 2, 24, 23, 461039), 'ip': '5.91.157.10', 'funcion': 'log_acceso', 'archivo': 'logRegister.py', 'linea': 608, 'error': 'No hubo error', 'codigoPostal': '12345', 'latitude': '41.8919', 'longitude': '12.5113', 'language': 'es'}]
(Background on this error at: https://sqlalche.me/e/14/e3q8)
____INTENTO ENTRAR____
127.0.0.1
None
Error registrando acceso: (pymysql.err.OperationalError) (1054, "Unknown column 'codigoPostal' in 'field list'")
[SQL: INSERT INTO logs (user_id, `userCuenta`, `accountCuenta`, fecha_log, ip, funcion, archivo, linea, error, `codigoPostal`, latitude, longitude, language) VALUES (%(user_id)s, %(userCuenta)s, %(accountCuenta)s, %(fecha_log)s, %(ip)s, %(funcion)s, %(archivo)s, %(linea)s, %(error)s, %(codigoPostal)s, %(latitude)s, %(longitude)s, %(language)s)]
[parameters: {'user_id': 28, 'userCuenta': 'usuario@example.com', 'accountCuenta': 'usuario@example.com', 'fecha_log': datetime.datetime(2025, 6, 23, 2, 24, 52, 973505), 'ip': '5.91.157.10', 'funcion': 'log_acceso', 'archivo': 'logRegister.py', 'linea': 608, 'error': 'No hubo error', 'codigoPostal': '12345', 'latitude': '41.8919', 'longitude': '12.5113', 'language': 'es'}]
(Background on this error at: https://sqlalche.me/e/14/e3q8)
Error registrando acceso: (pymysql.err.OperationalError) (1054, "Unknown column 'codigoPostal' in 'field list'")
[SQL: INSERT INTO logs (user_id, `userCuenta`, `accountCuenta`, fecha_log, ip, funcion, archivo, linea, error, `codigoPostal`, latitude, longitude, language) VALUES (%(user_id)s, %(userCuenta)s, %(accountCuenta)s, %(fecha_log)s, %(ip)s, %(funcion)s, %(archivo)s, %(linea)s, %(error)s, %(codigoPostal)s, %(latitude)s, %(longitude)s, %(language)s)]
[parameters: {'user_id': 28, 'userCuenta': 'usuario@example.com', 'accountCuenta': 'usuario@example.com', 'fecha_log': datetime.datetime(2025, 6, 23, 2, 32, 54, 91056), 'ip': '5.91.157.10', 'funcion': 'log_acceso', 'archivo': 'logRegister.py', 'linea': 608, 'error': 'No hubo error', 'codigoPostal': '12345', 'latitude': '41.8919', 'longitude': '12.5113', 'language': 'es'}]
(Background on this error at: https://sqlalche.me/e/14/e3q8)
Error registrando acceso: (pymysql.err.OperationalError) (1054, "Unknown column 'codigoPostal' in 'field list'")
[SQL: INSERT INTO logs (user_id, `userCuenta`, `accountCuenta`, fecha_log, ip, funcion, archivo, linea, error, `codigoPostal`, latitude, longitude, language) VALUES (%(user_id)s, %(userCuenta)s, %(accountCuenta)s, %(fecha_log)s, %(ip)s, %(funcion)s, %(archivo)s, %(linea)s, %(error)s, %(codigoPostal)s, %(latitude)s, %(longitude)s, %(language)s)]
[parameters: {'user_id': 28, 'userCuenta': 'usuario@example.com', 'accountCuenta': 'usuario@example.com', 'fecha_log': datetime.datetime(2025, 6, 23, 2, 33, 24, 35945), 'ip': '5.91.157.10', 'funcion': 'log_acceso', 'archivo': 'logRegister.py', 'linea': 608, 'error': 'No hubo error', 'codigoPostal': '12345', 'latitude': '41.8919', 'longitude': '12.5113', 'language': 'es'}]
(Background on this error at: https://sqlalche.me/e/14/e3q8)
Error registrando acceso: (pymysql.err.OperationalError) (1054, "Unknown column 'codigoPostal' in 'field list'")
[SQL: INSERT INTO logs (user_id, `userCuenta`, `accountCuenta`, fecha_log, ip, funcion, archivo, linea, error, `codigoPostal`, latitude, longitude, language) VALUES (%(user_id)s, %(userCuenta)s, %(accountCuenta)s, %(fecha_log)s, %(ip)s, %(funcion)s, %(archivo)s, %(linea)s, %(error)s, %(codigoPostal)s, %(latitude)s, %(longitude)s, %(language)s)]
[parameters: {'user_id': 28, 'userCuenta': 'usuario@example.com', 'accountCuenta': 'usuario@example.com', 'fecha_log': datetime.datetime(2025, 6, 23, 2, 36, 51, 337586), 'ip': '5.91.157.10', 'funcion': 'log_acceso', 'archivo': 'logRegister.py', 'linea': 608, 'error': 'No hubo error', 'codigoPostal': '12345', 'latitude': '41.8919', 'longitude': '12.5113', 'language': 'es'}]
(Background on this error at: https://sqlalche.me/e/14/e3q8)
Error registrando acceso: (pymysql.err.OperationalError) (1054, "Unknown column 'codigoPostal' in 'field list'")
[SQL: INSERT INTO logs (user_id, `userCuenta`, `accountCuenta`, fecha_log, ip, funcion, archivo, linea, error, `codigoPostal`, latitude, longitude, language) VALUES (%(user_id)s, %(userCuenta)s, %(accountCuenta)s, %(fecha_log)s, %(ip)s, %(funcion)s, %(archivo)s, %(linea)s, %(error)s, %(codigoPostal)s, %(latitude)s, %(longitude)s, %(language)s)]
[parameters: {'user_id': 28, 'userCuenta': 'usuario@example.com', 'accountCuenta': 'usuario@example.com', 'fecha_log': datetime.datetime(2025, 6, 23, 2, 37, 36, 141175), 'ip': '5.91.157.10', 'funcion': 'log_acceso', 'archivo': 'logRegister.py', 'linea': 608, 'error': 'No hubo error', 'codigoPostal': '12345', 'latitude': '41.8919', 'longitude': '12.5113', 'language': 'es'}]
(Background on this error at: https://sqlalche.me/e/14/e3q8)
Error registrando acceso: (pymysql.err.OperationalError) (1054, "Unknown column 'codigoPostal' in 'field list'")
[SQL: INSERT INTO logs (user_id, `userCuenta`, `accountCuenta`, fecha_log, ip, funcion, archivo, linea, error, `codigoPostal`, latitude, longitude, language) VALUES (%(user_id)s, %(userCuenta)s, %(accountCuenta)s, %(fecha_log)s, %(ip)s, %(funcion)s, %(archivo)s, %(linea)s, %(error)s, %(codigoPostal)s, %(latitude)s, %(longitude)s, %(language)s)]
[parameters: {'user_id': 28, 'userCuenta': 'usuario@example.com', 'accountCuenta': 'usuario@example.com', 'fecha_log': datetime.datetime(2025, 6, 23, 2, 38, 36, 918985), 'ip': '5.91.157.10', 'funcion': 'log_acceso', 'archivo': 'logRegister.py', 'linea': 608, 'error': 'No hubo error', 'codigoPostal': '12345', 'latitude': '41.8919', 'longitude': '12.5113', 'language': 'es'}]
(Background on this error at: https://sqlalche.me/e/14/e3q8)
____INTENTO ENTRAR____
127.0.0.1
None
Error registrando acceso: (pymysql.err.OperationalError) (1054, "Unknown column 'codigoPostal' in 'field list'")
[SQL: INSERT INTO logs (user_id, `userCuenta`, `accountCuenta`, fecha_log, ip, funcion, archivo, linea, error, `codigoPostal`, latitude, longitude, language) VALUES (%(user_id)s, %(userCuenta)s, %(accountCuenta)s, %(fecha_log)s, %(ip)s, %(funcion)s, %(archivo)s, %(linea)s, %(error)s, %(codigoPostal)s, %(latitude)s, %(longitude)s, %(language)s)]
[parameters: {'user_id': 28, 'userCuenta': 'usuario@example.com', 'accountCuenta': 'usuario@example.com', 'fecha_log': datetime.datetime(2025, 6, 23, 2, 40, 35, 421799), 'ip': '5.91.157.10', 'funcion': 'log_acceso', 'archivo': 'logRegister.py', 'linea': 608, 'error': 'No hubo error', 'codigoPostal': '12345', 'latitude': '41.8919', 'longitude': '12.5113', 'language': 'es'}]
(Background on this error at: https://sqlalche.me/e/14/e3q8)
Error registrando acceso: (pymysql.err.OperationalError) (1054, "Unknown column 'codigoPostal' in 'field list'")
[SQL: INSERT INTO logs (user_id, `userCuenta`, `accountCuenta`, fecha_log, ip, funcion, archivo, linea, error, `codigoPostal`, latitude, longitude, language) VALUES (%(user_id)s, %(userCuenta)s, %(accountCuenta)s, %(fecha_log)s, %(ip)s, %(funcion)s, %(archivo)s, %(linea)s, %(error)s, %(codigoPostal)s, %(latitude)s, %(longitude)s, %(language)s)]
[parameters: {'user_id': 28, 'userCuenta': 'usuario@example.com', 'accountCuenta': 'usuario@example.com', 'fecha_log': datetime.datetime(2025, 6, 23, 2, 48, 32, 882797), 'ip': '5.91.157.10', 'funcion': 'log_acceso', 'archivo': 'logRegister.py', 'linea': 608, 'error': 'No hubo error', 'codigoPostal': '12345', 'latitude': '41.8919', 'longitude': '12.5113', 'language': 'es'}]
(Background on this error at: https://sqlalche.me/e/14/e3q8)
Error registrando acceso: (pymysql.err.OperationalError) (1054, "Unknown column 'codigoPostal' in 'field list'")
[SQL: INSERT INTO logs (user_id, `userCuenta`, `accountCuenta`, fecha_log, ip, funcion, archivo, linea, error, `codigoPostal`, latitude, longitude, language) VALUES (%(user_id)s, %(userCuenta)s, %(accountCuenta)s, %(fecha_log)s, %(ip)s, %(funcion)s, %(archivo)s, %(linea)s, %(error)s, %(codigoPostal)s, %(latitude)s, %(longitude)s, %(language)s)]
[parameters: {'user_id': 28, 'userCuenta': 'usuario@example.com', 'accountCuenta': 'usuario@example.com', 'fecha_log': datetime.datetime(2025, 6, 23, 2, 50, 17, 972387), 'ip': '5.91.157.10', 'funcion': 'log_acceso', 'archivo': 'logRegister.py', 'linea': 608, 'error': 'No hubo error', 'codigoPostal': '4139', 'latitude': '41.8919', 'longitude': '12.5113', 'language': 'es'}]
(Background on this error at: https://sqlalche.me/e/14/e3q8)
Error registrando acceso: (pymysql.err.OperationalError) (1054, "Unknown column 'codigoPostal' in 'field list'")
[SQL: INSERT INTO logs (user_id, `userCuenta`, `accountCuenta`, fecha_log, ip, funcion, archivo, linea, error, `codigoPostal`, latitude, longitude, language) VALUES (%(user_id)s, %(userCuenta)s, %(accountCuenta)s, %(fecha_log)s, %(ip)s, %(funcion)s, %(archivo)s, %(linea)s, %(error)s, %(codigoPostal)s, %(latitude)s, %(longitude)s, %(language)s)]
[parameters: {'user_id': 28, 'userCuenta': 'usuario@example.com', 'accountCuenta': 'usuario@example.com', 'fecha_log': datetime.datetime(2025, 6, 23, 2, 51, 20, 569733), 'ip': '5.91.157.10', 'funcion': 'log_acceso', 'archivo': 'logRegister.py', 'linea': 608, 'error': 'No hubo error', 'codigoPostal': '4139', 'latitude': '41.8919', 'longitude': '12.5113', 'language': 'es'}]
(Background on this error at: https://sqlalche.me/e/14/e3q8)
Error registrando acceso: (pymysql.err.OperationalError) (1054, "Unknown column 'codigoPostal' in 'field list'")
[SQL: INSERT INTO logs (user_id, `userCuenta`, `accountCuenta`, fecha_log, ip, funcion, archivo, linea, error, `codigoPostal`, latitude, longitude, language) VALUES (%(user_id)s, %(userCuenta)s, %(accountCuenta)s, %(fecha_log)s, %(ip)s, %(funcion)s, %(archivo)s, %(linea)s, %(error)s, %(codigoPostal)s, %(latitude)s, %(longitude)s, %(language)s)]
[parameters: {'user_id': 28, 'userCuenta': 'usuario@example.com', 'accountCuenta': 'usuario@example.com', 'fecha_log': datetime.datetime(2025, 6, 23, 2, 51, 44, 639918), 'ip': '5.91.157.10', 'funcion': 'log_acceso', 'archivo': 'logRegister.py', 'linea': 608, 'error': 'No hubo error', 'codigoPostal': '4139', 'latitude': '41.8919', 'longitude': '12.5113', 'language': 'es'}]
(Background on this error at: https://sqlalche.me/e/14/e3q8)
Error registrando acceso: (pymysql.err.OperationalError) (1054, "Unknown column 'codigoPostal' in 'field list'")
[SQL: INSERT INTO logs (user_id, `userCuenta`, `accountCuenta`, fecha_log, ip, funcion, archivo, linea, error, `codigoPostal`, latitude, longitude, language) VALUES (%(user_id)s, %(userCuenta)s, %(accountCuenta)s, %(fecha_log)s, %(ip)s, %(funcion)s, %(archivo)s, %(linea)s, %(error)s, %(codigoPostal)s, %(latitude)s, %(longitude)s, %(language)s)]
[parameters: {'user_id': 28, 'userCuenta': 'usuario@example.com', 'accountCuenta': 'usuario@example.com', 'fecha_log': datetime.datetime(2025, 6, 23, 2, 52, 1, 595933), 'ip': '5.91.157.10', 'funcion': 'log_acceso', 'archivo': 'logRegister.py', 'linea': 608, 'error': 'No hubo error', 'codigoPostal': '4139', 'latitude': '41.8919', 'longitude': '12.5113', 'language': 'es'}]
(Background on this error at: https://sqlalche.me/e/14/e3q8)
Error registrando acceso: (pymysql.err.OperationalError) (1054, "Unknown column 'codigoPostal' in 'field list'")
[SQL: INSERT INTO logs (user_id, `userCuenta`, `accountCuenta`, fecha_log, ip, funcion, archivo, linea, error, `codigoPostal`, latitude, longitude, language) VALUES (%(user_id)s, %(userCuenta)s, %(accountCuenta)s, %(fecha_log)s, %(ip)s, %(funcion)s, %(archivo)s, %(linea)s, %(error)s, %(codigoPostal)s, %(latitude)s, %(longitude)s, %(language)s)]
[parameters: {'user_id': 28, 'userCuenta': 'usuario@example.com', 'accountCuenta': 'usuario@example.com', 'fecha_log': datetime.datetime(2025, 6, 23, 2, 57, 20, 5252), 'ip': '5.91.157.10', 'funcion': 'log_acceso', 'archivo': 'logRegister.py', 'linea': 608, 'error': 'No hubo error', 'codigoPostal': '4139', 'latitude': '41.8919', 'longitude': '12.5113', 'language': 'es'}]
(Background on this error at: https://sqlalche.me/e/14/e3q8)
Error registrando acceso: (pymysql.err.OperationalError) (1054, "Unknown column 'codigoPostal' in 'field list'")
[SQL: INSERT INTO logs (user_id, `userCuenta`, `accountCuenta`, fecha_log, ip, funcion, archivo, linea, error, `codigoPostal`, latitude, longitude, language) VALUES (%(user_id)s, %(userCuenta)s, %(accountCuenta)s, %(fecha_log)s, %(ip)s, %(funcion)s, %(archivo)s, %(linea)s, %(error)s, %(codigoPostal)s, %(latitude)s, %(longitude)s, %(language)s)]
[parameters: {'user_id': 28, 'userCuenta': 'usuario@example.com', 'accountCuenta': 'usuario@example.com', 'fecha_log': datetime.datetime(2025, 6, 23, 2, 57, 50, 973632), 'ip': '5.91.157.10', 'funcion': 'log_acceso', 'archivo': 'logRegister.py', 'linea': 608, 'error': 'No hubo error', 'codigoPostal': '4139', 'latitude': '41.8919', 'longitude': '12.5113', 'language': 'es'}]
(Background on this error at: https://sqlalche.me/e/14/e3q8)
Error registrando acceso: (pymysql.err.OperationalError) (1054, "Unknown column 'codigoPostal' in 'field list'")
[SQL: INSERT INTO logs (user_id, `userCuenta`, `accountCuenta`, fecha_log, ip, funcion, archivo, linea, error, `codigoPostal`, latitude, longitude, language) VALUES (%(user_id)s, %(userCuenta)s, %(accountCuenta)s, %(fecha_log)s, %(ip)s, %(funcion)s, %(archivo)s, %(linea)s, %(error)s, %(codigoPostal)s, %(latitude)s, %(longitude)s, %(language)s)]
[parameters: {'user_id': 28, 'userCuenta': 'usuario@example.com', 'accountCuenta': 'usuario@example.com', 'fecha_log': datetime.datetime(2025, 6, 23, 2, 58, 34, 561380), 'ip': '5.91.157.10', 'funcion': 'log_acceso', 'archivo': 'logRegister.py', 'linea': 608, 'error': 'No hubo error', 'codigoPostal': '4139', 'latitude': '41.8919', 'longitude': '12.5113', 'language': 'es'}]
(Background on this error at: https://sqlalche.me/e/14/e3q8)
Error registrando acceso: (pymysql.err.OperationalError) (1054, "Unknown column 'codigoPostal' in 'field list'")
[SQL: INSERT INTO logs (user_id, `userCuenta`, `accountCuenta`, fecha_log, ip, funcion, archivo, linea, error, `codigoPostal`, latitude, longitude, language) VALUES (%(user_id)s, %(userCuenta)s, %(accountCuenta)s, %(fecha_log)s, %(ip)s, %(funcion)s, %(archivo)s, %(linea)s, %(error)s, %(codigoPostal)s, %(latitude)s, %(longitude)s, %(language)s)]
[parameters: {'user_id': 28, 'userCuenta': 'usuario@example.com', 'accountCuenta': 'usuario@example.com', 'fecha_log': datetime.datetime(2025, 6, 23, 2, 59, 45, 984141), 'ip': '5.91.157.10', 'funcion': 'log_acceso', 'archivo': 'logRegister.py', 'linea': 608, 'error': 'No hubo error', 'codigoPostal': '4139', 'latitude': '41.8919', 'longitude': '12.5113', 'language': 'es'}]
(Background on this error at: https://sqlalche.me/e/14/e3q8)
Error registrando acceso: (pymysql.err.OperationalError) (1054, "Unknown column 'codigoPostal' in 'field list'")
[SQL: INSERT INTO logs (user_id, `userCuenta`, `accountCuenta`, fecha_log, ip, funcion, archivo, linea, error, `codigoPostal`, latitude, longitude, language) VALUES (%(user_id)s, %(userCuenta)s, %(accountCuenta)s, %(fecha_log)s, %(ip)s, %(funcion)s, %(archivo)s, %(linea)s, %(error)s, %(codigoPostal)s, %(latitude)s, %(longitude)s, %(language)s)]
[parameters: {'user_id': 28, 'userCuenta': 'usuario@example.com', 'accountCuenta': 'usuario@example.com', 'fecha_log': datetime.datetime(2025, 6, 23, 3, 3, 44, 125481), 'ip': '5.91.157.10', 'funcion': 'log_acceso', 'archivo': 'logRegister.py', 'linea': 608, 'error': 'No hubo error', 'codigoPostal': '4139', 'latitude': '41.8919', 'longitude': '12.5113', 'language': 'es'}]
(Background on this error at: https://sqlalche.me/e/14/e3q8)
Error registrando acceso: (pymysql.err.OperationalError) (1054, "Unknown column 'codigoPostal' in 'field list'")
[SQL: INSERT INTO logs (user_id, `userCuenta`, `accountCuenta`, fecha_log, ip, funcion, archivo, linea, error, `codigoPostal`, latitude, longitude, language) VALUES (%(user_id)s, %(userCuenta)s, %(accountCuenta)s, %(fecha_log)s, %(ip)s, %(funcion)s, %(archivo)s, %(linea)s, %(error)s, %(codigoPostal)s, %(latitude)s, %(longitude)s, %(language)s)]
[parameters: {'user_id': 28, 'userCuenta': 'usuario@example.com', 'accountCuenta': 'usuario@example.com', 'fecha_log': datetime.datetime(2025, 6, 23, 3, 4, 48, 412687), 'ip': '5.91.157.10', 'funcion': 'log_acceso', 'archivo': 'logRegister.py', 'linea': 608, 'error': 'No hubo error', 'codigoPostal': '4139', 'latitude': '41.8919', 'longitude': '12.5113', 'language': 'es'}]
(Background on this error at: https://sqlalche.me/e/14/e3q8)
____INTENTO ENTRAR____
127.0.0.1
None
Error registrando acceso: (pymysql.err.OperationalError) (1054, "Unknown column 'codigoPostal' in 'field list'")
[SQL: INSERT INTO logs (user_id, `userCuenta`, `accountCuenta`, fecha_log, ip, funcion, archivo, linea, error, `codigoPostal`, latitude, longitude, language) VALUES (%(user_id)s, %(userCuenta)s, %(accountCuenta)s, %(fecha_log)s, %(ip)s, %(funcion)s, %(archivo)s, %(linea)s, %(error)s, %(codigoPostal)s, %(latitude)s, %(longitude)s, %(language)s)]
[parameters: {'user_id': 28, 'userCuenta': 'usuario@example.com', 'accountCuenta': 'usuario@example.com', 'fecha_log': datetime.datetime(2025, 6, 23, 3, 5, 11, 467741), 'ip': '5.91.157.10', 'funcion': 'log_acceso', 'archivo': 'logRegister.py', 'linea': 608, 'error': 'No hubo error', 'codigoPostal': '4139', 'latitude': '41.8919', 'longitude': '12.5113', 'language': 'es'}]
(Background on this error at: https://sqlalche.me/e/14/e3q8)
Debugging message: Configuración de logger completada.
Este es un mensaje de info.
Este es un mensaje de advertencia.
Este es un mensaje de error.
Este es un mensaje crítico.
Debugging message: Configuración de logger completada.
Este es un mensaje de info.
Este es un mensaje de advertencia.
Este es un mensaje de error.
Este es un mensaje crítico.
Debugging message: Configuración de logger completada.
Este es un mensaje de info.
Este es un mensaje de advertencia.
Este es un mensaje de error.
Este es un mensaje crítico.
Error registrando acceso: (pymysql.err.OperationalError) (2003, "Can't connect to MySQL server on '23.22.109.80' ([Errno 111] Connection refused)")
(Background on this error at: https://sqlalche.me/e/14/e3q8)
Debugging message: Configuración de logger completada.
Este es un mensaje de info.
Este es un mensaje de advertencia.
Este es un mensaje de error.
Este es un mensaje crítico.
Debugging message: Configuración de logger completada.
Este es un mensaje de info.
Este es un mensaje de advertencia.
Este es un mensaje de error.
Este es un mensaje crítico.
Debugging message: Configuración de logger completada.
Este es un mensaje de info.
Este es un mensaje de advertencia.
Este es un mensaje de error.
Este es un mensaje crítico.
Debugging message: Configuración de logger completada.
Este es un mensaje de info.
Este es un mensaje de advertencia.
Este es un mensaje de error.
Este es un mensaje crítico.
Debugging message: Configuración de logger completada.
Este es un mensaje de info.
Este es un mensaje de advertencia.
Este es un mensaje de error.
Este es un mensaje crítico.
Exception on / [GET]
Traceback (most recent call last):
  File "/usr/local/lib/python3.9/site-packages/pymysql/connections.py", line 613, in connect
    sock = socket.create_connection(
  File "/usr/local/lib/python3.9/socket.py", line 844, in create_connection
    raise err
  File "/usr/local/lib/python3.9/socket.py", line 832, in create_connection
    sock.connect(sa)
ConnectionRefusedError: [Errno 111] Connection refused

During handling of the above exception, another exception occurred:

Traceback (most recent call last):
  File "/usr/local/lib/python3.9/site-packages/sqlalchemy/engine/base.py", line 3250, in _wrap_pool_connect
    return fn()
  File "/usr/local/lib/python3.9/site-packages/sqlalchemy/pool/base.py", line 310, in connect
    return _ConnectionFairy._checkout(self)
  File "/usr/local/lib/python3.9/site-packages/sqlalchemy/pool/base.py", line 868, in _checkout
    fairy = _ConnectionRecord.checkout(pool)
  File "/usr/local/lib/python3.9/site-packages/sqlalchemy/pool/base.py", line 476, in checkout
    rec = pool._do_get()
  File "/usr/local/lib/python3.9/site-packages/sqlalchemy/pool/impl.py", line 146, in _do_get
    self._dec_overflow()
  File "/usr/local/lib/python3.9/site-packages/sqlalchemy/util/langhelpers.py", line 70, in __exit__
    compat.raise_(
  File "/usr/local/lib/python3.9/site-packages/sqlalchemy/util/compat.py", line 207, in raise_
    raise exception
  File "/usr/local/lib/python3.9/site-packages/sqlalchemy/pool/impl.py", line 143, in _do_get
    return self._create_connection()
  File "/usr/local/lib/python3.9/site-packages/sqlalchemy/pool/base.py", line 256, in _create_connection
    return _ConnectionRecord(self)
  File "/usr/local/lib/python3.9/site-packages/sqlalchemy/pool/base.py", line 371, in __init__
    self.__connect()
  File "/usr/local/lib/python3.9/site-packages/sqlalchemy/pool/base.py", line 666, in __connect
    pool.logger.debug("Error on connect(): %s", e)
  File "/usr/local/lib/python3.9/site-packages/sqlalchemy/util/langhelpers.py", line 70, in __exit__
    compat.raise_(
  File "/usr/local/lib/python3.9/site-packages/sqlalchemy/util/compat.py", line 207, in raise_
    raise exception
  File "/usr/local/lib/python3.9/site-packages/sqlalchemy/pool/base.py", line 661, in __connect
    self.dbapi_connection = connection = pool._invoke_creator(self)
  File "/usr/local/lib/python3.9/site-packages/sqlalchemy/engine/create.py", line 590, in connect
    return dialect.connect(*cargs, **cparams)
  File "/usr/local/lib/python3.9/site-packages/sqlalchemy/engine/default.py", line 597, in connect
    return self.dbapi.connect(*cargs, **cparams)
  File "/usr/local/lib/python3.9/site-packages/pymysql/connections.py", line 353, in __init__
    self.connect()
  File "/usr/local/lib/python3.9/site-packages/pymysql/connections.py", line 664, in connect
    raise exc
pymysql.err.OperationalError: (2003, "Can't connect to MySQL server on '127.0.0.1' ([Errno 111] Connection refused)")

The above exception was the direct cause of the following exception:

Traceback (most recent call last):
  File "/usr/local/lib/python3.9/site-packages/flask/app.py", line 2528, in wsgi_app
    response = self.full_dispatch_request()
  File "/usr/local/lib/python3.9/site-packages/flask/app.py", line 1825, in full_dispatch_request
    rv = self.handle_user_exception(e)
  File "/usr/local/lib/python3.9/site-packages/flask_cors/extension.py", line 165, in wrapped_function
    return cors_after_request(app.make_response(f(*args, **kwargs)))
  File "/usr/local/lib/python3.9/site-packages/flask/app.py", line 1823, in full_dispatch_request
    rv = self.dispatch_request()
  File "/usr/local/lib/python3.9/site-packages/flask/app.py", line 1799, in dispatch_request
    return self.ensure_sync(self.view_functions[rule.endpoint])(**view_args)
  File "/workspaces/bot421/src/app.py", line 714, in entrada
    crea_tablas_DB()
  File "/workspaces/bot421/src/models/creaTablas.py", line 34, in crea_tablas_DB
    Usuario.crear_tabla_usuarios()
  File "/workspaces/bot421/src/models/usuario.py", line 60, in crear_tabla_usuarios
    insp = inspect(db.engine)
  File "/usr/local/lib/python3.9/site-packages/sqlalchemy/inspection.py", line 64, in inspect
    ret = reg(subject)
  File "/usr/local/lib/python3.9/site-packages/sqlalchemy/engine/reflection.py", line 182, in _engine_insp
    return Inspector._construct(Inspector._init_engine, bind)
  File "/usr/local/lib/python3.9/site-packages/sqlalchemy/engine/reflection.py", line 117, in _construct
    init(self, bind)
  File "/usr/local/lib/python3.9/site-packages/sqlalchemy/engine/reflection.py", line 128, in _init_engine
    engine.connect().close()
  File "/usr/local/lib/python3.9/site-packages/sqlalchemy/engine/base.py", line 3204, in connect
    return self._connection_cls(self, close_with_result=close_with_result)
  File "/usr/local/lib/python3.9/site-packages/sqlalchemy/engine/base.py", line 96, in __init__
    else engine.raw_connection()
  File "/usr/local/lib/python3.9/site-packages/sqlalchemy/engine/base.py", line 3283, in raw_connection
    return self._wrap_pool_connect(self.pool.connect, _connection)
  File "/usr/local/lib/python3.9/site-packages/sqlalchemy/engine/base.py", line 3253, in _wrap_pool_connect
    Connection._handle_dbapi_exception_noconnection(
  File "/usr/local/lib/python3.9/site-packages/sqlalchemy/engine/base.py", line 2100, in _handle_dbapi_exception_noconnection
    util.raise_(
  File "/usr/local/lib/python3.9/site-packages/sqlalchemy/util/compat.py", line 207, in raise_
    raise exception
  File "/usr/local/lib/python3.9/site-packages/sqlalchemy/engine/base.py", line 3250, in _wrap_pool_connect
    return fn()
  File "/usr/local/lib/python3.9/site-packages/sqlalchemy/pool/base.py", line 310, in connect
    return _ConnectionFairy._checkout(self)
  File "/usr/local/lib/python3.9/site-packages/sqlalchemy/pool/base.py", line 868, in _checkout
    fairy = _ConnectionRecord.checkout(pool)
  File "/usr/local/lib/python3.9/site-packages/sqlalchemy/pool/base.py", line 476, in checkout
    rec = pool._do_get()
  File "/usr/local/lib/python3.9/site-packages/sqlalchemy/pool/impl.py", line 146, in _do_get
    self._dec_overflow()
  File "/usr/local/lib/python3.9/site-packages/sqlalchemy/util/langhelpers.py", line 70, in __exit__
    compat.raise_(
  File "/usr/local/lib/python3.9/site-packages/sqlalchemy/util/compat.py", line 207, in raise_
    raise exception
  File "/usr/local/lib/python3.9/site-packages/sqlalchemy/pool/impl.py", line 143, in _do_get
    return self._create_connection()
  File "/usr/local/lib/python3.9/site-packages/sqlalchemy/pool/base.py", line 256, in _create_connection
    return _ConnectionRecord(self)
  File "/usr/local/lib/python3.9/site-packages/sqlalchemy/pool/base.py", line 371, in __init__
    self.__connect()
  File "/usr/local/lib/python3.9/site-packages/sqlalchemy/pool/base.py", line 666, in __connect
    pool.logger.debug("Error on connect(): %s", e)
  File "/usr/local/lib/python3.9/site-packages/sqlalchemy/util/langhelpers.py", line 70, in __exit__
    compat.raise_(
  File "/usr/local/lib/python3.9/site-packages/sqlalchemy/util/compat.py", line 207, in raise_
    raise exception
  File "/usr/local/lib/python3.9/site-packages/sqlalchemy/pool/base.py", line 661, in __connect
    self.dbapi_connection = connection = pool._invoke_creator(self)
  File "/usr/local/lib/python3.9/site-packages/sqlalchemy/engine/create.py", line 590, in connect
    return dialect.connect(*cargs, **cparams)
  File "/usr/local/lib/python3.9/site-packages/sqlalchemy/engine/default.py", line 597, in connect
    return self.dbapi.connect(*cargs, **cparams)
  File "/usr/local/lib/python3.9/site-packages/pymysql/connections.py", line 353, in __init__
    self.connect()
  File "/usr/local/lib/python3.9/site-packages/pymysql/connections.py", line 664, in connect
    raise exc
sqlalchemy.exc.OperationalError: (pymysql.err.OperationalError) (2003, "Can't connect to MySQL server on '127.0.0.1' ([Errno 111] Connection refused)")
(Background on this error at: https://sqlalche.me/e/14/e3q8)
Exception on /favicon.ico/ [GET]
Traceback (most recent call last):
  File "/usr/local/lib/python3.9/site-packages/pymysql/connections.py", line 613, in connect
    sock = socket.create_connection(
  File "/usr/local/lib/python3.9/socket.py", line 844, in create_connection
    raise err
  File "/usr/local/lib/python3.9/socket.py", line 832, in create_connection
    sock.connect(sa)
ConnectionRefusedError: [Errno 111] Connection refused

During handling of the above exception, another exception occurred:

Traceback (most recent call last):
  File "/usr/local/lib/python3.9/site-packages/sqlalchemy/engine/base.py", line 3250, in _wrap_pool_connect
    return fn()
  File "/usr/local/lib/python3.9/site-packages/sqlalchemy/pool/base.py", line 310, in connect
    return _ConnectionFairy._checkout(self)
  File "/usr/local/lib/python3.9/site-packages/sqlalchemy/pool/base.py", line 868, in _checkout
    fairy = _ConnectionRecord.checkout(pool)
  File "/usr/local/lib/python3.9/site-packages/sqlalchemy/pool/base.py", line 476, in checkout
    rec = pool._do_get()
  File "/usr/local/lib/python3.9/site-packages/sqlalchemy/pool/impl.py", line 146, in _do_get
    self._dec_overflow()
  File "/usr/local/lib/python3.9/site-packages/sqlalchemy/util/langhelpers.py", line 70, in __exit__
    compat.raise_(
  File "/usr/local/lib/python3.9/site-packages/sqlalchemy/util/compat.py", line 207, in raise_
    raise exception
  File "/usr/local/lib/python3.9/site-packages/sqlalchemy/pool/impl.py", line 143, in _do_get
    return self._create_connection()
  File "/usr/local/lib/python3.9/site-packages/sqlalchemy/pool/base.py", line 256, in _create_connection
    return _ConnectionRecord(self)
  File "/usr/local/lib/python3.9/site-packages/sqlalchemy/pool/base.py", line 371, in __init__
    self.__connect()
  File "/usr/local/lib/python3.9/site-packages/sqlalchemy/pool/base.py", line 666, in __connect
    pool.logger.debug("Error on connect(): %s", e)
  File "/usr/local/lib/python3.9/site-packages/sqlalchemy/util/langhelpers.py", line 70, in __exit__
    compat.raise_(
  File "/usr/local/lib/python3.9/site-packages/sqlalchemy/util/compat.py", line 207, in raise_
    raise exception
  File "/usr/local/lib/python3.9/site-packages/sqlalchemy/pool/base.py", line 661, in __connect
    self.dbapi_connection = connection = pool._invoke_creator(self)
  File "/usr/local/lib/python3.9/site-packages/sqlalchemy/engine/create.py", line 590, in connect
    return dialect.connect(*cargs, **cparams)
  File "/usr/local/lib/python3.9/site-packages/sqlalchemy/engine/default.py", line 597, in connect
    return self.dbapi.connect(*cargs, **cparams)
  File "/usr/local/lib/python3.9/site-packages/pymysql/connections.py", line 353, in __init__
    self.connect()
  File "/usr/local/lib/python3.9/site-packages/pymysql/connections.py", line 664, in connect
    raise exc
pymysql.err.OperationalError: (2003, "Can't connect to MySQL server on '127.0.0.1' ([Errno 111] Connection refused)")

The above exception was the direct cause of the following exception:

Traceback (most recent call last):
  File "/usr/local/lib/python3.9/site-packages/flask/app.py", line 2528, in wsgi_app
    response = self.full_dispatch_request()
  File "/usr/local/lib/python3.9/site-packages/flask/app.py", line 1825, in full_dispatch_request
    rv = self.handle_user_exception(e)
  File "/usr/local/lib/python3.9/site-packages/flask_cors/extension.py", line 165, in wrapped_function
    return cors_after_request(app.make_response(f(*args, **kwargs)))
  File "/usr/local/lib/python3.9/site-packages/flask/app.py", line 1823, in full_dispatch_request
    rv = self.dispatch_request()
  File "/usr/local/lib/python3.9/site-packages/flask/app.py", line 1799, in dispatch_request
    return self.ensure_sync(self.view_functions[rule.endpoint])(**view_args)
  File "/workspaces/bot421/src/app.py", line 714, in entrada
    crea_tablas_DB()
  File "/workspaces/bot421/src/models/creaTablas.py", line 34, in crea_tablas_DB
    Usuario.crear_tabla_usuarios()
  File "/workspaces/bot421/src/models/usuario.py", line 60, in crear_tabla_usuarios
    insp = inspect(db.engine)
  File "/usr/local/lib/python3.9/site-packages/sqlalchemy/inspection.py", line 64, in inspect
    ret = reg(subject)
  File "/usr/local/lib/python3.9/site-packages/sqlalchemy/engine/reflection.py", line 182, in _engine_insp
    return Inspector._construct(Inspector._init_engine, bind)
  File "/usr/local/lib/python3.9/site-packages/sqlalchemy/engine/reflection.py", line 117, in _construct
    init(self, bind)
  File "/usr/local/lib/python3.9/site-packages/sqlalchemy/engine/reflection.py", line 128, in _init_engine
    engine.connect().close()
  File "/usr/local/lib/python3.9/site-packages/sqlalchemy/engine/base.py", line 3204, in connect
    return self._connection_cls(self, close_with_result=close_with_result)
  File "/usr/local/lib/python3.9/site-packages/sqlalchemy/engine/base.py", line 96, in __init__
    else engine.raw_connection()
  File "/usr/local/lib/python3.9/site-packages/sqlalchemy/engine/base.py", line 3283, in raw_connection
    return self._wrap_pool_connect(self.pool.connect, _connection)
  File "/usr/local/lib/python3.9/site-packages/sqlalchemy/engine/base.py", line 3253, in _wrap_pool_connect
    Connection._handle_dbapi_exception_noconnection(
  File "/usr/local/lib/python3.9/site-packages/sqlalchemy/engine/base.py", line 2100, in _handle_dbapi_exception_noconnection
    util.raise_(
  File "/usr/local/lib/python3.9/site-packages/sqlalchemy/util/compat.py", line 207, in raise_
    raise exception
  File "/usr/local/lib/python3.9/site-packages/sqlalchemy/engine/base.py", line 3250, in _wrap_pool_connect
    return fn()
  File "/usr/local/lib/python3.9/site-packages/sqlalchemy/pool/base.py", line 310, in connect
    return _ConnectionFairy._checkout(self)
  File "/usr/local/lib/python3.9/site-packages/sqlalchemy/pool/base.py", line 868, in _checkout
    fairy = _ConnectionRecord.checkout(pool)
  File "/usr/local/lib/python3.9/site-packages/sqlalchemy/pool/base.py", line 476, in checkout
    rec = pool._do_get()
  File "/usr/local/lib/python3.9/site-packages/sqlalchemy/pool/impl.py", line 146, in _do_get
    self._dec_overflow()
  File "/usr/local/lib/python3.9/site-packages/sqlalchemy/util/langhelpers.py", line 70, in __exit__
    compat.raise_(
  File "/usr/local/lib/python3.9/site-packages/sqlalchemy/util/compat.py", line 207, in raise_
    raise exception
  File "/usr/local/lib/python3.9/site-packages/sqlalchemy/pool/impl.py", line 143, in _do_get
    return self._create_connection()
  File "/usr/local/lib/python3.9/site-packages/sqlalchemy/pool/base.py", line 256, in _create_connection
    return _ConnectionRecord(self)
  File "/usr/local/lib/python3.9/site-packages/sqlalchemy/pool/base.py", line 371, in __init__
    self.__connect()
  File "/usr/local/lib/python3.9/site-packages/sqlalchemy/pool/base.py", line 666, in __connect
    pool.logger.debug("Error on connect(): %s", e)
  File "/usr/local/lib/python3.9/site-packages/sqlalchemy/util/langhelpers.py", line 70, in __exit__
    compat.raise_(
  File "/usr/local/lib/python3.9/site-packages/sqlalchemy/util/compat.py", line 207, in raise_
    raise exception
  File "/usr/local/lib/python3.9/site-packages/sqlalchemy/pool/base.py", line 661, in __connect
    self.dbapi_connection = connection = pool._invoke_creator(self)
  File "/usr/local/lib/python3.9/site-packages/sqlalchemy/engine/create.py", line 590, in connect
    return dialect.connect(*cargs, **cparams)
  File "/usr/local/lib/python3.9/site-packages/sqlalchemy/engine/default.py", line 597, in connect
    return self.dbapi.connect(*cargs, **cparams)
  File "/usr/local/lib/python3.9/site-packages/pymysql/connections.py", line 353, in __init__
    self.connect()
  File "/usr/local/lib/python3.9/site-packages/pymysql/connections.py", line 664, in connect
    raise exc
sqlalchemy.exc.OperationalError: (pymysql.err.OperationalError) (2003, "Can't connect to MySQL server on '127.0.0.1' ([Errno 111] Connection refused)")
(Background on this error at: https://sqlalche.me/e/14/e3q8)
Exception on / [GET]
Traceback (most recent call last):
  File "/usr/local/lib/python3.9/site-packages/pymysql/connections.py", line 613, in connect
    sock = socket.create_connection(
  File "/usr/local/lib/python3.9/socket.py", line 844, in create_connection
    raise err
  File "/usr/local/lib/python3.9/socket.py", line 832, in create_connection
    sock.connect(sa)
ConnectionRefusedError: [Errno 111] Connection refused

During handling of the above exception, another exception occurred:

Traceback (most recent call last):
  File "/usr/local/lib/python3.9/site-packages/sqlalchemy/engine/base.py", line 3250, in _wrap_pool_connect
    return fn()
  File "/usr/local/lib/python3.9/site-packages/sqlalchemy/pool/base.py", line 310, in connect
    return _ConnectionFairy._checkout(self)
  File "/usr/local/lib/python3.9/site-packages/sqlalchemy/pool/base.py", line 868, in _checkout
    fairy = _ConnectionRecord.checkout(pool)
  File "/usr/local/lib/python3.9/site-packages/sqlalchemy/pool/base.py", line 476, in checkout
    rec = pool._do_get()
  File "/usr/local/lib/python3.9/site-packages/sqlalchemy/pool/impl.py", line 146, in _do_get
    self._dec_overflow()
  File "/usr/local/lib/python3.9/site-packages/sqlalchemy/util/langhelpers.py", line 70, in __exit__
    compat.raise_(
  File "/usr/local/lib/python3.9/site-packages/sqlalchemy/util/compat.py", line 207, in raise_
    raise exception
  File "/usr/local/lib/python3.9/site-packages/sqlalchemy/pool/impl.py", line 143, in _do_get
    return self._create_connection()
  File "/usr/local/lib/python3.9/site-packages/sqlalchemy/pool/base.py", line 256, in _create_connection
    return _ConnectionRecord(self)
  File "/usr/local/lib/python3.9/site-packages/sqlalchemy/pool/base.py", line 371, in __init__
    self.__connect()
  File "/usr/local/lib/python3.9/site-packages/sqlalchemy/pool/base.py", line 666, in __connect
    pool.logger.debug("Error on connect(): %s", e)
  File "/usr/local/lib/python3.9/site-packages/sqlalchemy/util/langhelpers.py", line 70, in __exit__
    compat.raise_(
  File "/usr/local/lib/python3.9/site-packages/sqlalchemy/util/compat.py", line 207, in raise_
    raise exception
  File "/usr/local/lib/python3.9/site-packages/sqlalchemy/pool/base.py", line 661, in __connect
    self.dbapi_connection = connection = pool._invoke_creator(self)
  File "/usr/local/lib/python3.9/site-packages/sqlalchemy/engine/create.py", line 590, in connect
    return dialect.connect(*cargs, **cparams)
  File "/usr/local/lib/python3.9/site-packages/sqlalchemy/engine/default.py", line 597, in connect
    return self.dbapi.connect(*cargs, **cparams)
  File "/usr/local/lib/python3.9/site-packages/pymysql/connections.py", line 353, in __init__
    self.connect()
  File "/usr/local/lib/python3.9/site-packages/pymysql/connections.py", line 664, in connect
    raise exc
pymysql.err.OperationalError: (2003, "Can't connect to MySQL server on '127.0.0.1' ([Errno 111] Connection refused)")

The above exception was the direct cause of the following exception:

Traceback (most recent call last):
  File "/usr/local/lib/python3.9/site-packages/flask/app.py", line 2528, in wsgi_app
    response = self.full_dispatch_request()
  File "/usr/local/lib/python3.9/site-packages/flask/app.py", line 1825, in full_dispatch_request
    rv = self.handle_user_exception(e)
  File "/usr/local/lib/python3.9/site-packages/flask_cors/extension.py", line 165, in wrapped_function
    return cors_after_request(app.make_response(f(*args, **kwargs)))
  File "/usr/local/lib/python3.9/site-packages/flask/app.py", line 1823, in full_dispatch_request
    rv = self.dispatch_request()
  File "/usr/local/lib/python3.9/site-packages/flask/app.py", line 1799, in dispatch_request
    return self.ensure_sync(self.view_functions[rule.endpoint])(**view_args)
  File "/workspaces/bot421/src/app.py", line 714, in entrada
    crea_tablas_DB()
  File "/workspaces/bot421/src/models/creaTablas.py", line 34, in crea_tablas_DB
    Usuario.crear_tabla_usuarios()
  File "/workspaces/bot421/src/models/usuario.py", line 60, in crear_tabla_usuarios
    insp = inspect(db.engine)
  File "/usr/local/lib/python3.9/site-packages/sqlalchemy/inspection.py", line 64, in inspect
    ret = reg(subject)
  File "/usr/local/lib/python3.9/site-packages/sqlalchemy/engine/reflection.py", line 182, in _engine_insp
    return Inspector._construct(Inspector._init_engine, bind)
  File "/usr/local/lib/python3.9/site-packages/sqlalchemy/engine/reflection.py", line 117, in _construct
    init(self, bind)
  File "/usr/local/lib/python3.9/site-packages/sqlalchemy/engine/reflection.py", line 128, in _init_engine
    engine.connect().close()
  File "/usr/local/lib/python3.9/site-packages/sqlalchemy/engine/base.py", line 3204, in connect
    return self._connection_cls(self, close_with_result=close_with_result)
  File "/usr/local/lib/python3.9/site-packages/sqlalchemy/engine/base.py", line 96, in __init__
    else engine.raw_connection()
  File "/usr/local/lib/python3.9/site-packages/sqlalchemy/engine/base.py", line 3283, in raw_connection
    return self._wrap_pool_connect(self.pool.connect, _connection)
  File "/usr/local/lib/python3.9/site-packages/sqlalchemy/engine/base.py", line 3253, in _wrap_pool_connect
    Connection._handle_dbapi_exception_noconnection(
  File "/usr/local/lib/python3.9/site-packages/sqlalchemy/engine/base.py", line 2100, in _handle_dbapi_exception_noconnection
    util.raise_(
  File "/usr/local/lib/python3.9/site-packages/sqlalchemy/util/compat.py", line 207, in raise_
    raise exception
  File "/usr/local/lib/python3.9/site-packages/sqlalchemy/engine/base.py", line 3250, in _wrap_pool_connect
    return fn()
  File "/usr/local/lib/python3.9/site-packages/sqlalchemy/pool/base.py", line 310, in connect
    return _ConnectionFairy._checkout(self)
  File "/usr/local/lib/python3.9/site-packages/sqlalchemy/pool/base.py", line 868, in _checkout
    fairy = _ConnectionRecord.checkout(pool)
  File "/usr/local/lib/python3.9/site-packages/sqlalchemy/pool/base.py", line 476, in checkout
    rec = pool._do_get()
  File "/usr/local/lib/python3.9/site-packages/sqlalchemy/pool/impl.py", line 146, in _do_get
    self._dec_overflow()
  File "/usr/local/lib/python3.9/site-packages/sqlalchemy/util/langhelpers.py", line 70, in __exit__
    compat.raise_(
  File "/usr/local/lib/python3.9/site-packages/sqlalchemy/util/compat.py", line 207, in raise_
    raise exception
  File "/usr/local/lib/python3.9/site-packages/sqlalchemy/pool/impl.py", line 143, in _do_get
    return self._create_connection()
  File "/usr/local/lib/python3.9/site-packages/sqlalchemy/pool/base.py", line 256, in _create_connection
    return _ConnectionRecord(self)
  File "/usr/local/lib/python3.9/site-packages/sqlalchemy/pool/base.py", line 371, in __init__
    self.__connect()
  File "/usr/local/lib/python3.9/site-packages/sqlalchemy/pool/base.py", line 666, in __connect
    pool.logger.debug("Error on connect(): %s", e)
  File "/usr/local/lib/python3.9/site-packages/sqlalchemy/util/langhelpers.py", line 70, in __exit__
    compat.raise_(
  File "/usr/local/lib/python3.9/site-packages/sqlalchemy/util/compat.py", line 207, in raise_
    raise exception
  File "/usr/local/lib/python3.9/site-packages/sqlalchemy/pool/base.py", line 661, in __connect
    self.dbapi_connection = connection = pool._invoke_creator(self)
  File "/usr/local/lib/python3.9/site-packages/sqlalchemy/engine/create.py", line 590, in connect
    return dialect.connect(*cargs, **cparams)
  File "/usr/local/lib/python3.9/site-packages/sqlalchemy/engine/default.py", line 597, in connect
    return self.dbapi.connect(*cargs, **cparams)
  File "/usr/local/lib/python3.9/site-packages/pymysql/connections.py", line 353, in __init__
    self.connect()
  File "/usr/local/lib/python3.9/site-packages/pymysql/connections.py", line 664, in connect
    raise exc
sqlalchemy.exc.OperationalError: (pymysql.err.OperationalError) (2003, "Can't connect to MySQL server on '127.0.0.1' ([Errno 111] Connection refused)")
(Background on this error at: https://sqlalche.me/e/14/e3q8)
Exception on /favicon.ico/ [GET]
Traceback (most recent call last):
  File "/usr/local/lib/python3.9/site-packages/pymysql/connections.py", line 613, in connect
    sock = socket.create_connection(
  File "/usr/local/lib/python3.9/socket.py", line 844, in create_connection
    raise err
  File "/usr/local/lib/python3.9/socket.py", line 832, in create_connection
    sock.connect(sa)
ConnectionRefusedError: [Errno 111] Connection refused

During handling of the above exception, another exception occurred:

Traceback (most recent call last):
  File "/usr/local/lib/python3.9/site-packages/sqlalchemy/engine/base.py", line 3250, in _wrap_pool_connect
    return fn()
  File "/usr/local/lib/python3.9/site-packages/sqlalchemy/pool/base.py", line 310, in connect
    return _ConnectionFairy._checkout(self)
  File "/usr/local/lib/python3.9/site-packages/sqlalchemy/pool/base.py", line 868, in _checkout
    fairy = _ConnectionRecord.checkout(pool)
  File "/usr/local/lib/python3.9/site-packages/sqlalchemy/pool/base.py", line 476, in checkout
    rec = pool._do_get()
  File "/usr/local/lib/python3.9/site-packages/sqlalchemy/pool/impl.py", line 146, in _do_get
    self._dec_overflow()
  File "/usr/local/lib/python3.9/site-packages/sqlalchemy/util/langhelpers.py", line 70, in __exit__
    compat.raise_(
  File "/usr/local/lib/python3.9/site-packages/sqlalchemy/util/compat.py", line 207, in raise_
    raise exception
  File "/usr/local/lib/python3.9/site-packages/sqlalchemy/pool/impl.py", line 143, in _do_get
    return self._create_connection()
  File "/usr/local/lib/python3.9/site-packages/sqlalchemy/pool/base.py", line 256, in _create_connection
    return _ConnectionRecord(self)
  File "/usr/local/lib/python3.9/site-packages/sqlalchemy/pool/base.py", line 371, in __init__
    self.__connect()
  File "/usr/local/lib/python3.9/site-packages/sqlalchemy/pool/base.py", line 666, in __connect
    pool.logger.debug("Error on connect(): %s", e)
  File "/usr/local/lib/python3.9/site-packages/sqlalchemy/util/langhelpers.py", line 70, in __exit__
    compat.raise_(
  File "/usr/local/lib/python3.9/site-packages/sqlalchemy/util/compat.py", line 207, in raise_
    raise exception
  File "/usr/local/lib/python3.9/site-packages/sqlalchemy/pool/base.py", line 661, in __connect
    self.dbapi_connection = connection = pool._invoke_creator(self)
  File "/usr/local/lib/python3.9/site-packages/sqlalchemy/engine/create.py", line 590, in connect
    return dialect.connect(*cargs, **cparams)
  File "/usr/local/lib/python3.9/site-packages/sqlalchemy/engine/default.py", line 597, in connect
    return self.dbapi.connect(*cargs, **cparams)
  File "/usr/local/lib/python3.9/site-packages/pymysql/connections.py", line 353, in __init__
    self.connect()
  File "/usr/local/lib/python3.9/site-packages/pymysql/connections.py", line 664, in connect
    raise exc
pymysql.err.OperationalError: (2003, "Can't connect to MySQL server on '127.0.0.1' ([Errno 111] Connection refused)")

The above exception was the direct cause of the following exception:

Traceback (most recent call last):
  File "/usr/local/lib/python3.9/site-packages/flask/app.py", line 2528, in wsgi_app
    response = self.full_dispatch_request()
  File "/usr/local/lib/python3.9/site-packages/flask/app.py", line 1825, in full_dispatch_request
    rv = self.handle_user_exception(e)
  File "/usr/local/lib/python3.9/site-packages/flask_cors/extension.py", line 165, in wrapped_function
    return cors_after_request(app.make_response(f(*args, **kwargs)))
  File "/usr/local/lib/python3.9/site-packages/flask/app.py", line 1823, in full_dispatch_request
    rv = self.dispatch_request()
  File "/usr/local/lib/python3.9/site-packages/flask/app.py", line 1799, in dispatch_request
    return self.ensure_sync(self.view_functions[rule.endpoint])(**view_args)
  File "/workspaces/bot421/src/app.py", line 714, in entrada
    crea_tablas_DB()
  File "/workspaces/bot421/src/models/creaTablas.py", line 34, in crea_tablas_DB
    Usuario.crear_tabla_usuarios()
  File "/workspaces/bot421/src/models/usuario.py", line 60, in crear_tabla_usuarios
    insp = inspect(db.engine)
  File "/usr/local/lib/python3.9/site-packages/sqlalchemy/inspection.py", line 64, in inspect
    ret = reg(subject)
  File "/usr/local/lib/python3.9/site-packages/sqlalchemy/engine/reflection.py", line 182, in _engine_insp
    return Inspector._construct(Inspector._init_engine, bind)
  File "/usr/local/lib/python3.9/site-packages/sqlalchemy/engine/reflection.py", line 117, in _construct
    init(self, bind)
  File "/usr/local/lib/python3.9/site-packages/sqlalchemy/engine/reflection.py", line 128, in _init_engine
    engine.connect().close()
  File "/usr/local/lib/python3.9/site-packages/sqlalchemy/engine/base.py", line 3204, in connect
    return self._connection_cls(self, close_with_result=close_with_result)
  File "/usr/local/lib/python3.9/site-packages/sqlalchemy/engine/base.py", line 96, in __init__
    else engine.raw_connection()
  File "/usr/local/lib/python3.9/site-packages/sqlalchemy/engine/base.py", line 3283, in raw_connection
    return self._wrap_pool_connect(self.pool.connect, _connection)
  File "/usr/local/lib/python3.9/site-packages/sqlalchemy/engine/base.py", line 3253, in _wrap_pool_connect
    Connection._handle_dbapi_exception_noconnection(
  File "/usr/local/lib/python3.9/site-packages/sqlalchemy/engine/base.py", line 2100, in _handle_dbapi_exception_noconnection
    util.raise_(
  File "/usr/local/lib/python3.9/site-packages/sqlalchemy/util/compat.py", line 207, in raise_
    raise exception
  File "/usr/local/lib/python3.9/site-packages/sqlalchemy/engine/base.py", line 3250, in _wrap_pool_connect
    return fn()
  File "/usr/local/lib/python3.9/site-packages/sqlalchemy/pool/base.py", line 310, in connect
    return _ConnectionFairy._checkout(self)
  File "/usr/local/lib/python3.9/site-packages/sqlalchemy/pool/base.py", line 868, in _checkout
    fairy = _ConnectionRecord.checkout(pool)
  File "/usr/local/lib/python3.9/site-packages/sqlalchemy/pool/base.py", line 476, in checkout
    rec = pool._do_get()
  File "/usr/local/lib/python3.9/site-packages/sqlalchemy/pool/impl.py", line 146, in _do_get
    self._dec_overflow()
  File "/usr/local/lib/python3.9/site-packages/sqlalchemy/util/langhelpers.py", line 70, in __exit__
    compat.raise_(
  File "/usr/local/lib/python3.9/site-packages/sqlalchemy/util/compat.py", line 207, in raise_
    raise exception
  File "/usr/local/lib/python3.9/site-packages/sqlalchemy/pool/impl.py", line 143, in _do_get
    return self._create_connection()
  File "/usr/local/lib/python3.9/site-packages/sqlalchemy/pool/base.py", line 256, in _create_connection
    return _ConnectionRecord(self)
  File "/usr/local/lib/python3.9/site-packages/sqlalchemy/pool/base.py", line 371, in __init__
    self.__connect()
  File "/usr/local/lib/python3.9/site-packages/sqlalchemy/pool/base.py", line 666, in __connect
    pool.logger.debug("Error on connect(): %s", e)
  File "/usr/local/lib/python3.9/site-packages/sqlalchemy/util/langhelpers.py", line 70, in __exit__
    compat.raise_(
  File "/usr/local/lib/python3.9/site-packages/sqlalchemy/util/compat.py", line 207, in raise_
    raise exception
  File "/usr/local/lib/python3.9/site-packages/sqlalchemy/pool/base.py", line 661, in __connect
    self.dbapi_connection = connection = pool._invoke_creator(self)
  File "/usr/local/lib/python3.9/site-packages/sqlalchemy/engine/create.py", line 590, in connect
    return dialect.connect(*cargs, **cparams)
  File "/usr/local/lib/python3.9/site-packages/sqlalchemy/engine/default.py", line 597, in connect
    return self.dbapi.connect(*cargs, **cparams)
  File "/usr/local/lib/python3.9/site-packages/pymysql/connections.py", line 353, in __init__
    self.connect()
  File "/usr/local/lib/python3.9/site-packages/pymysql/connections.py", line 664, in connect
    raise exc
sqlalchemy.exc.OperationalError: (pymysql.err.OperationalError) (2003, "Can't connect to MySQL server on '127.0.0.1' ([Errno 111] Connection refused)")
(Background on this error at: https://sqlalche.me/e/14/e3q8)
Debugging message: Configuración de logger completada.
Este es un mensaje de info.
Este es un mensaje de advertencia.
Este es un mensaje de error.
Este es un mensaje crítico.
Debugging message: Configuración de logger completada.
Este es un mensaje de info.
Este es un mensaje de advertencia.
Este es un mensaje de error.
Este es un mensaje crítico.
Error registrando acceso: (pymysql.err.OperationalError) (2003, "Can't connect to MySQL server on '127.0.0.1' ([Errno 111] Connection refused)")
(Background on this error at: https://sqlalche.me/e/14/e3q8)
Debugging message: Configuración de logger completada.
Este es un mensaje de info.
Este es un mensaje de advertencia.
Este es un mensaje de error.
Este es un mensaje crítico.
Debugging message: Configuración de logger completada.
Este es un mensaje de info.
Este es un mensaje de advertencia.
Este es un mensaje de error.
Este es un mensaje crítico.
____INTENTO ENTRAR____
127.0.0.1
None
Debugging message: Configuración de logger completada.
Este es un mensaje de info.
Este es un mensaje de advertencia.
Este es un mensaje de error.
Este es un mensaje crítico.
____INTENTO ENTRAR____
127.0.0.1
None
Debugging message: Configuración de logger completada.
Este es un mensaje de info.
Este es un mensaje de advertencia.
Este es un mensaje de error.
Este es un mensaje crítico.
____INTENTO ENTRAR____
127.0.0.1
None
Debugging message: Configuración de logger completada.
Este es un mensaje de info.
Este es un mensaje de advertencia.
Este es un mensaje de error.
Este es un mensaje crítico.
____INTENTO ENTRAR____
127.0.0.1
None
Debugging message: Configuración de logger completada.
Este es un mensaje de info.
Este es un mensaje de advertencia.
Este es un mensaje de error.
Este es un mensaje crítico.
____INTENTO ENTRAR____
127.0.0.1
None
emilianooliveto02@gmail.com
____INTENTO ENTRAR____
127.0.0.1
None
